[2025-07-27T08:09:31.314+0000] {local_task_job_runner.py:123} INFO - ::group::Pre task execution logs
[2025-07-27T08:09:31.340+0000] {taskinstance.py:2614} INFO - Dependencies all met for dep_context=non-requeueable deps ti=<TaskInstance: fraud_detection_training.execute_training manual__2025-07-27T08:09:28.317575+00:00 [queued]>
[2025-07-27T08:09:31.351+0000] {taskinstance.py:2614} INFO - Dependencies all met for dep_context=requeueable deps ti=<TaskInstance: fraud_detection_training.execute_training manual__2025-07-27T08:09:28.317575+00:00 [queued]>
[2025-07-27T08:09:31.351+0000] {taskinstance.py:2867} INFO - Starting attempt 1 of 1
[2025-07-27T08:09:31.367+0000] {taskinstance.py:2890} INFO - Executing <Task(PythonOperator): execute_training> on 2025-07-27 08:09:28.317575+00:00
[2025-07-27T08:09:31.374+0000] {standard_task_runner.py:104} INFO - Running: ['***', 'tasks', 'run', 'fraud_detection_training', 'execute_training', 'manual__2025-07-27T08:09:28.317575+00:00', '--job-id', '55', '--raw', '--subdir', 'DAGS_FOLDER/fraud_detection_training_dag.py', '--cfg-path', '/tmp/tmp5jcgoqwg']
[2025-07-27T08:09:31.375+0000] {standard_task_runner.py:105} INFO - Job 55: Subtask execute_training
[2025-07-27T08:09:31.373+0000] {warnings.py:112} WARNING - /home/***/.local/lib/python3.12/site-packages/***/task/task_runner/standard_task_runner.py:70: DeprecationWarning: This process (pid=350) is multi-threaded, use of fork() may lead to deadlocks in the child.
  pid = os.fork()

[2025-07-27T08:09:31.376+0000] {standard_task_runner.py:72} INFO - Started process 351 to run task
[2025-07-27T08:09:31.410+0000] {task_command.py:467} INFO - Running <TaskInstance: fraud_detection_training.execute_training manual__2025-07-27T08:09:28.317575+00:00 [running]> on host ff2b233a1e22
[2025-07-27T08:09:31.480+0000] {taskinstance.py:3134} INFO - Exporting env vars: AIRFLOW_CTX_DAG_OWNER='kanewyp' AIRFLOW_CTX_DAG_ID='fraud_detection_training' AIRFLOW_CTX_TASK_ID='execute_training' AIRFLOW_CTX_EXECUTION_DATE='2025-07-27T08:09:28.317575+00:00' AIRFLOW_CTX_TRY_NUMBER='1' AIRFLOW_CTX_DAG_RUN_ID='manual__2025-07-27T08:09:28.317575+00:00'
[2025-07-27T08:09:31.481+0000] {taskinstance.py:732} INFO - ::endgroup::
[2025-07-27T08:09:35.159+0000] {fraud_detection_training_dag.py:22} INFO - Initializing Fraud Detection Training
[2025-07-27T08:09:35.169+0000] {fraud_detection_training.py:62} INFO - Configuration loaded successfully
[2025-07-27T08:09:35.869+0000] {fraud_detection_training.py:88} INFO - Connected to MinIO. Available buckets: mlflow
[2025-07-27T08:09:36.017+0000] {fraud_detection_training.py:182} INFO - Starting model training process...
[2025-07-27T08:09:36.018+0000] {fraud_detection_training.py:104} INFO - Reading data from Kafka topic: transactions
[2025-07-27T08:09:36.393+0000] {conn.py:396} INFO - <BrokerConnection client_id=kafka-python-2.2.15, node_id=bootstrap-0 host=pkc-ldvj1.ap-southeast-2.aws.confluent.cloud:9092 <connecting> [IPv4 ('52.64.27.176', 9092)]>: connecting to pkc-ldvj1.ap-southeast-2.aws.confluent.cloud:9092 [('52.64.27.176', 9092) IPv4]
[2025-07-27T08:09:36.449+0000] {conn.py:497} INFO - <BrokerConnection client_id=kafka-python-2.2.15, node_id=bootstrap-0 host=pkc-ldvj1.ap-southeast-2.aws.confluent.cloud:9092 <handshake> [IPv4 ('52.64.27.176', 9092)]>: Loading system default SSL CAs from ('/usr/lib/ssl/cert.pem', '/usr/lib/ssl/certs', 'SSL_CERT_FILE', '/usr/lib/ssl/cert.pem', 'SSL_CERT_DIR', '/usr/lib/ssl/certs')
[2025-07-27T08:09:36.589+0000] {conn.py:618} INFO - <BrokerConnection client_id=kafka-python-2.2.15, node_id=bootstrap-0 host=pkc-ldvj1.ap-southeast-2.aws.confluent.cloud:9092 <checking_api_versions_recv> [IPv4 ('52.64.27.176', 9092)]>: Broker version identified as 2.6
[2025-07-27T08:09:36.750+0000] {conn.py:822} INFO - <BrokerConnection client_id=kafka-python-2.2.15, node_id=bootstrap-0 host=pkc-ldvj1.ap-southeast-2.aws.confluent.cloud:9092 <authenticating> [IPv4 ('52.64.27.176', 9092)]>: Authenticated as KQIWVOLDBVJZDLTP via SASL / Plain
[2025-07-27T08:09:36.752+0000] {conn.py:467} INFO - <BrokerConnection client_id=kafka-python-2.2.15, node_id=bootstrap-0 host=pkc-ldvj1.ap-southeast-2.aws.confluent.cloud:9092 <connected> [IPv4 ('52.64.27.176', 9092)]>: Connection complete.
[2025-07-27T08:09:36.753+0000] {consumer.py:120} WARNING - group_id is None: disabling auto-commit.
[2025-07-27T08:09:36.753+0000] {subscription_state.py:181} INFO - Updating subscribed topics to: ('transactions',)
[2025-07-27T08:09:36.754+0000] {logging_mixin.py:190} INFO - <kafka.consumer.group.KafkaConsumer object at 0x7f0f55a6d160>
[2025-07-27T08:09:36.795+0000] {subscription_state.py:254} INFO - Updated partition assignment: [('transactions', 0), ('transactions', 1), ('transactions', 2), ('transactions', 3), ('transactions', 4), ('transactions', 5)]
[2025-07-27T08:09:37.082+0000] {conn.py:396} INFO - <BrokerConnection client_id=kafka-python-2.2.15, node_id=0 host=b0-pkc-ldvj1.ap-southeast-2.aws.confluent.cloud:9092 <connecting> [IPv4 ('13.237.213.69', 9092)]>: connecting to b0-pkc-ldvj1.ap-southeast-2.aws.confluent.cloud:9092 [('13.237.213.69', 9092) IPv4]
[2025-07-27T08:09:37.503+0000] {conn.py:396} INFO - <BrokerConnection client_id=kafka-python-2.2.15, node_id=1 host=b1-pkc-ldvj1.ap-southeast-2.aws.confluent.cloud:9092 <connecting> [IPv4 ('13.238.192.73', 9092)]>: connecting to b1-pkc-ldvj1.ap-southeast-2.aws.confluent.cloud:9092 [('13.238.192.73', 9092) IPv4]
[2025-07-27T08:09:47.535+0000] {conn.py:1516} WARNING - DNS lookup failed for b2-pkc-ldvj1.ap-southeast-2.aws.confluent.cloud:9092, exception was [Errno -3] Temporary failure in name resolution. Is your advertised.listeners (called advertised.host.name before Kafka 9) correct and resolvable?
[2025-07-27T08:09:47.647+0000] {conn.py:323} ERROR - <BrokerConnection client_id=kafka-python-2.2.15, node_id=2 host=b2-pkc-ldvj1.ap-southeast-2.aws.confluent.cloud:9092 <connecting> [unspecified None]>: DNS lookup failed for b2-pkc-ldvj1.ap-southeast-2.aws.confluent.cloud:9092 (0)
[2025-07-27T08:09:47.767+0000] {conn.py:945} ERROR - <BrokerConnection client_id=kafka-python-2.2.15, node_id=2 host=b2-pkc-ldvj1.ap-southeast-2.aws.confluent.cloud:9092 <connecting> [unspecified None]>: Closing connection. KafkaConnectionError: DNS failure
[2025-07-27T08:09:47.889+0000] {client_async.py:388} WARNING - Node 2 connection failed -- refreshing metadata
[2025-07-27T08:09:51.434+0000] {job.py:229} INFO - Heartbeat recovered after 14.87 seconds
[2025-07-27T08:09:51.761+0000] {conn.py:396} INFO - <BrokerConnection client_id=kafka-python-2.2.15, node_id=3 host=b3-pkc-ldvj1.ap-southeast-2.aws.confluent.cloud:9092 <connecting> [IPv4 ('3.106.149.208', 9092)]>: connecting to b3-pkc-ldvj1.ap-southeast-2.aws.confluent.cloud:9092 [('3.106.149.208', 9092) IPv4]
[2025-07-27T08:09:51.939+0000] {conn.py:396} INFO - <BrokerConnection client_id=kafka-python-2.2.15, node_id=4 host=b4-pkc-ldvj1.ap-southeast-2.aws.confluent.cloud:9092 <connecting> [IPv4 ('13.54.68.137', 9092)]>: connecting to b4-pkc-ldvj1.ap-southeast-2.aws.confluent.cloud:9092 [('13.54.68.137', 9092) IPv4]
[2025-07-27T08:09:52.352+0000] {conn.py:396} INFO - <BrokerConnection client_id=kafka-python-2.2.15, node_id=5 host=b5-pkc-ldvj1.ap-southeast-2.aws.confluent.cloud:9092 <connecting> [IPv4 ('52.64.157.42', 9092)]>: connecting to b5-pkc-ldvj1.ap-southeast-2.aws.confluent.cloud:9092 [('52.64.157.42', 9092) IPv4]
[2025-07-27T08:09:52.371+0000] {conn.py:497} INFO - <BrokerConnection client_id=kafka-python-2.2.15, node_id=0 host=b0-pkc-ldvj1.ap-southeast-2.aws.confluent.cloud:9092 <handshake> [IPv4 ('13.237.213.69', 9092)]>: Loading system default SSL CAs from ('/usr/lib/ssl/cert.pem', '/usr/lib/ssl/certs', 'SSL_CERT_FILE', '/usr/lib/ssl/cert.pem', 'SSL_CERT_DIR', '/usr/lib/ssl/certs')
[2025-07-27T08:09:52.396+0000] {conn.py:497} INFO - <BrokerConnection client_id=kafka-python-2.2.15, node_id=1 host=b1-pkc-ldvj1.ap-southeast-2.aws.confluent.cloud:9092 <handshake> [IPv4 ('13.238.192.73', 9092)]>: Loading system default SSL CAs from ('/usr/lib/ssl/cert.pem', '/usr/lib/ssl/certs', 'SSL_CERT_FILE', '/usr/lib/ssl/cert.pem', 'SSL_CERT_DIR', '/usr/lib/ssl/certs')
[2025-07-27T08:09:52.419+0000] {conn.py:497} INFO - <BrokerConnection client_id=kafka-python-2.2.15, node_id=3 host=b3-pkc-ldvj1.ap-southeast-2.aws.confluent.cloud:9092 <handshake> [IPv4 ('3.106.149.208', 9092)]>: Loading system default SSL CAs from ('/usr/lib/ssl/cert.pem', '/usr/lib/ssl/certs', 'SSL_CERT_FILE', '/usr/lib/ssl/cert.pem', 'SSL_CERT_DIR', '/usr/lib/ssl/certs')
[2025-07-27T08:09:52.439+0000] {conn.py:497} INFO - <BrokerConnection client_id=kafka-python-2.2.15, node_id=4 host=b4-pkc-ldvj1.ap-southeast-2.aws.confluent.cloud:9092 <handshake> [IPv4 ('13.54.68.137', 9092)]>: Loading system default SSL CAs from ('/usr/lib/ssl/cert.pem', '/usr/lib/ssl/certs', 'SSL_CERT_FILE', '/usr/lib/ssl/cert.pem', 'SSL_CERT_DIR', '/usr/lib/ssl/certs')
[2025-07-27T08:09:52.460+0000] {conn.py:945} INFO - <BrokerConnection client_id=kafka-python-2.2.15, node_id=bootstrap-0 host=pkc-ldvj1.ap-southeast-2.aws.confluent.cloud:9092 <connected> [IPv4 ('52.64.27.176', 9092)]>: Closing connection. 
[2025-07-27T08:09:52.461+0000] {conn.py:945} INFO - <BrokerConnection client_id=kafka-python-2.2.15, node_id=0 host=b0-pkc-ldvj1.ap-southeast-2.aws.confluent.cloud:9092 <handshake> [IPv4 ('13.237.213.69', 9092)]>: Closing connection. 
[2025-07-27T08:09:52.462+0000] {conn.py:945} INFO - <BrokerConnection client_id=kafka-python-2.2.15, node_id=1 host=b1-pkc-ldvj1.ap-southeast-2.aws.confluent.cloud:9092 <handshake> [IPv4 ('13.238.192.73', 9092)]>: Closing connection. 
[2025-07-27T08:09:52.462+0000] {conn.py:945} INFO - <BrokerConnection client_id=kafka-python-2.2.15, node_id=3 host=b3-pkc-ldvj1.ap-southeast-2.aws.confluent.cloud:9092 <handshake> [IPv4 ('3.106.149.208', 9092)]>: Closing connection. 
[2025-07-27T08:09:52.463+0000] {conn.py:945} INFO - <BrokerConnection client_id=kafka-python-2.2.15, node_id=4 host=b4-pkc-ldvj1.ap-southeast-2.aws.confluent.cloud:9092 <handshake> [IPv4 ('13.54.68.137', 9092)]>: Closing connection. 
[2025-07-27T08:09:52.464+0000] {conn.py:945} INFO - <BrokerConnection client_id=kafka-python-2.2.15, node_id=5 host=b5-pkc-ldvj1.ap-southeast-2.aws.confluent.cloud:9092 <connecting> [IPv4 ('52.64.157.42', 9092)]>: Closing connection. 
[2025-07-27T08:09:52.482+0000] {fraud_detection_training.py:135} ERROR - Failed to read data from Kafka: No message received from Kafka
Traceback (most recent call last):
  File "/opt/airflow/dags/fraud_detection_training.py", line 123, in _read_data_from_kafka
    raise ValueError('No message received from Kafka')
ValueError: No message received from Kafka
[2025-07-27T08:09:52.483+0000] {fraud_detection_training.py:337} ERROR - Training failed: No message received from Kafka
Traceback (most recent call last):
  File "/opt/airflow/dags/fraud_detection_training.py", line 185, in train_model
    df = self._read_data_from_kafka()
         ^^^^^^^^^^^^^^^^^^^^^^^^^^^^
  File "/opt/airflow/dags/fraud_detection_training.py", line 123, in _read_data_from_kafka
    raise ValueError('No message received from Kafka')
ValueError: No message received from Kafka
[2025-07-27T08:09:52.484+0000] {fraud_detection_training_dag.py:28} ERROR - Training failed: No message received from Kafka
Traceback (most recent call last):
  File "/opt/airflow/dags/fraud_detection_training_dag.py", line 24, in _train_model
    model, precision = trainer.train_model()
                       ^^^^^^^^^^^^^^^^^^^^^
  File "/opt/airflow/dags/fraud_detection_training.py", line 185, in train_model
    df = self._read_data_from_kafka()
         ^^^^^^^^^^^^^^^^^^^^^^^^^^^^
  File "/opt/airflow/dags/fraud_detection_training.py", line 123, in _read_data_from_kafka
    raise ValueError('No message received from Kafka')
ValueError: No message received from Kafka
[2025-07-27T08:09:52.634+0000] {taskinstance.py:3313} ERROR - Task failed with exception
Traceback (most recent call last):
  File "/opt/airflow/dags/fraud_detection_training_dag.py", line 24, in _train_model
    model, precision = trainer.train_model()
                       ^^^^^^^^^^^^^^^^^^^^^
  File "/opt/airflow/dags/fraud_detection_training.py", line 185, in train_model
    df = self._read_data_from_kafka()
         ^^^^^^^^^^^^^^^^^^^^^^^^^^^^
  File "/opt/airflow/dags/fraud_detection_training.py", line 123, in _read_data_from_kafka
    raise ValueError('No message received from Kafka')
ValueError: No message received from Kafka

During handling of the above exception, another exception occurred:

Traceback (most recent call last):
  File "/home/airflow/.local/lib/python3.12/site-packages/airflow/models/taskinstance.py", line 768, in _execute_task
    result = _execute_callable(context=context, **execute_callable_kwargs)
             ^^^^^^^^^^^^^^^^^^^^^^^^^^^^^^^^^^^^^^^^^^^^^^^^^^^^^^^^^^^^^
  File "/home/airflow/.local/lib/python3.12/site-packages/airflow/models/taskinstance.py", line 734, in _execute_callable
    return ExecutionCallableRunner(
           ^^^^^^^^^^^^^^^^^^^^^^^^
  File "/home/airflow/.local/lib/python3.12/site-packages/airflow/utils/operator_helpers.py", line 252, in run
    return self.func(*args, **kwargs)
           ^^^^^^^^^^^^^^^^^^^^^^^^^^
  File "/home/airflow/.local/lib/python3.12/site-packages/airflow/models/baseoperator.py", line 424, in wrapper
    return func(self, *args, **kwargs)
           ^^^^^^^^^^^^^^^^^^^^^^^^^^^
  File "/home/airflow/.local/lib/python3.12/site-packages/airflow/operators/python.py", line 238, in execute
    return_value = self.execute_callable()
                   ^^^^^^^^^^^^^^^^^^^^^^^
  File "/home/airflow/.local/lib/python3.12/site-packages/airflow/operators/python.py", line 256, in execute_callable
    return runner.run(*self.op_args, **self.op_kwargs)
           ^^^^^^^^^^^^^^^^^^^^^^^^^^^^^^^^^^^^^^^^^^^
  File "/home/airflow/.local/lib/python3.12/site-packages/airflow/utils/operator_helpers.py", line 252, in run
    return self.func(*args, **kwargs)
           ^^^^^^^^^^^^^^^^^^^^^^^^^^
  File "/opt/airflow/dags/fraud_detection_training_dag.py", line 29, in _train_model
    raise AirflowException(f"Model Training failed: {str(e)}")
airflow.exceptions.AirflowException: Model Training failed: No message received from Kafka
[2025-07-27T08:09:52.653+0000] {taskinstance.py:1226} INFO - Marking task as FAILED. dag_id=fraud_detection_training, task_id=execute_training, run_id=manual__2025-07-27T08:09:28.317575+00:00, execution_date=20250727T080928, start_date=20250727T080931, end_date=20250727T080952
[2025-07-27T08:09:52.705+0000] {taskinstance.py:341} INFO - ::group::Post task execution logs
[2025-07-27T08:09:52.705+0000] {standard_task_runner.py:124} ERROR - Failed to execute job 55 for task execute_training (Model Training failed: No message received from Kafka; 351)
Traceback (most recent call last):
  File "/opt/airflow/dags/fraud_detection_training_dag.py", line 24, in _train_model
    model, precision = trainer.train_model()
                       ^^^^^^^^^^^^^^^^^^^^^
  File "/opt/airflow/dags/fraud_detection_training.py", line 185, in train_model
    df = self._read_data_from_kafka()
         ^^^^^^^^^^^^^^^^^^^^^^^^^^^^
  File "/opt/airflow/dags/fraud_detection_training.py", line 123, in _read_data_from_kafka
    raise ValueError('No message received from Kafka')
ValueError: No message received from Kafka

During handling of the above exception, another exception occurred:

Traceback (most recent call last):
  File "/home/airflow/.local/lib/python3.12/site-packages/airflow/task/task_runner/standard_task_runner.py", line 117, in _start_by_fork
    ret = args.func(args, dag=self.dag)
          ^^^^^^^^^^^^^^^^^^^^^^^^^^^^^
  File "/home/airflow/.local/lib/python3.12/site-packages/airflow/cli/cli_config.py", line 49, in command
    return func(*args, **kwargs)
           ^^^^^^^^^^^^^^^^^^^^^
  File "/home/airflow/.local/lib/python3.12/site-packages/airflow/utils/cli.py", line 116, in wrapper
    return f(*args, **kwargs)
           ^^^^^^^^^^^^^^^^^^
  File "/home/airflow/.local/lib/python3.12/site-packages/airflow/cli/commands/task_command.py", line 483, in task_run
    task_return_code = _run_task_by_selected_method(args, _dag, ti)
                       ^^^^^^^^^^^^^^^^^^^^^^^^^^^^^^^^^^^^^^^^^^^^
  File "/home/airflow/.local/lib/python3.12/site-packages/airflow/cli/commands/task_command.py", line 256, in _run_task_by_selected_method
    return _run_raw_task(args, ti)
           ^^^^^^^^^^^^^^^^^^^^^^^
  File "/home/airflow/.local/lib/python3.12/site-packages/airflow/cli/commands/task_command.py", line 341, in _run_raw_task
    return ti._run_raw_task(
           ^^^^^^^^^^^^^^^^^
  File "/home/airflow/.local/lib/python3.12/site-packages/airflow/utils/session.py", line 97, in wrapper
    return func(*args, session=session, **kwargs)
           ^^^^^^^^^^^^^^^^^^^^^^^^^^^^^^^^^^^^^^
  File "/home/airflow/.local/lib/python3.12/site-packages/airflow/models/taskinstance.py", line 3006, in _run_raw_task
    return _run_raw_task(
           ^^^^^^^^^^^^^^
  File "/home/airflow/.local/lib/python3.12/site-packages/airflow/models/taskinstance.py", line 274, in _run_raw_task
    TaskInstance._execute_task_with_callbacks(
  File "/home/airflow/.local/lib/python3.12/site-packages/airflow/models/taskinstance.py", line 3161, in _execute_task_with_callbacks
    result = self._execute_task(context, task_orig)
             ^^^^^^^^^^^^^^^^^^^^^^^^^^^^^^^^^^^^^^
  File "/home/airflow/.local/lib/python3.12/site-packages/airflow/models/taskinstance.py", line 3185, in _execute_task
    return _execute_task(self, context, task_orig)
           ^^^^^^^^^^^^^^^^^^^^^^^^^^^^^^^^^^^^^^^
  File "/home/airflow/.local/lib/python3.12/site-packages/airflow/models/taskinstance.py", line 768, in _execute_task
    result = _execute_callable(context=context, **execute_callable_kwargs)
             ^^^^^^^^^^^^^^^^^^^^^^^^^^^^^^^^^^^^^^^^^^^^^^^^^^^^^^^^^^^^^
  File "/home/airflow/.local/lib/python3.12/site-packages/airflow/models/taskinstance.py", line 734, in _execute_callable
    return ExecutionCallableRunner(
           ^^^^^^^^^^^^^^^^^^^^^^^^
  File "/home/airflow/.local/lib/python3.12/site-packages/airflow/utils/operator_helpers.py", line 252, in run
    return self.func(*args, **kwargs)
           ^^^^^^^^^^^^^^^^^^^^^^^^^^
  File "/home/airflow/.local/lib/python3.12/site-packages/airflow/models/baseoperator.py", line 424, in wrapper
    return func(self, *args, **kwargs)
           ^^^^^^^^^^^^^^^^^^^^^^^^^^^
  File "/home/airflow/.local/lib/python3.12/site-packages/airflow/operators/python.py", line 238, in execute
    return_value = self.execute_callable()
                   ^^^^^^^^^^^^^^^^^^^^^^^
  File "/home/airflow/.local/lib/python3.12/site-packages/airflow/operators/python.py", line 256, in execute_callable
    return runner.run(*self.op_args, **self.op_kwargs)
           ^^^^^^^^^^^^^^^^^^^^^^^^^^^^^^^^^^^^^^^^^^^
  File "/home/airflow/.local/lib/python3.12/site-packages/airflow/utils/operator_helpers.py", line 252, in run
    return self.func(*args, **kwargs)
           ^^^^^^^^^^^^^^^^^^^^^^^^^^
  File "/opt/airflow/dags/fraud_detection_training_dag.py", line 29, in _train_model
    raise AirflowException(f"Model Training failed: {str(e)}")
airflow.exceptions.AirflowException: Model Training failed: No message received from Kafka
[2025-07-27T08:09:52.755+0000] {local_task_job_runner.py:266} INFO - Task exited with return code 1
[2025-07-27T08:09:52.798+0000] {taskinstance.py:3901} INFO - 1 downstream tasks scheduled from follow-on schedule check
[2025-07-27T08:09:52.800+0000] {local_task_job_runner.py:245} INFO - ::endgroup::
