[2025-08-03T10:22:19.937+0000] {local_task_job_runner.py:123} INFO - ::group::Pre task execution logs
[2025-08-03T10:22:19.972+0000] {taskinstance.py:2614} INFO - Dependencies all met for dep_context=non-requeueable deps ti=<TaskInstance: fraud_detection_training.execute_training manual__2025-08-03T10:22:14.002760+00:00 [queued]>
[2025-08-03T10:22:19.982+0000] {taskinstance.py:2614} INFO - Dependencies all met for dep_context=requeueable deps ti=<TaskInstance: fraud_detection_training.execute_training manual__2025-08-03T10:22:14.002760+00:00 [queued]>
[2025-08-03T10:22:19.983+0000] {taskinstance.py:2867} INFO - Starting attempt 1 of 1
[2025-08-03T10:22:19.995+0000] {taskinstance.py:2890} INFO - Executing <Task(PythonOperator): execute_training> on 2025-08-03 10:22:14.002760+00:00
[2025-08-03T10:22:20.002+0000] {warnings.py:112} WARNING - /home/***/.local/lib/python3.12/site-packages/***/task/task_runner/standard_task_runner.py:70: DeprecationWarning: This process (pid=4059) is multi-threaded, use of fork() may lead to deadlocks in the child.
  pid = os.fork()

[2025-08-03T10:22:20.003+0000] {standard_task_runner.py:104} INFO - Running: ['***', 'tasks', 'run', 'fraud_detection_training', 'execute_training', 'manual__2025-08-03T10:22:14.002760+00:00', '--job-id', '111', '--raw', '--subdir', 'DAGS_FOLDER/fraud_detection_training_dag.py', '--cfg-path', '/tmp/tmptabrj79r']
[2025-08-03T10:22:20.004+0000] {standard_task_runner.py:105} INFO - Job 111: Subtask execute_training
[2025-08-03T10:22:20.004+0000] {standard_task_runner.py:72} INFO - Started process 4060 to run task
[2025-08-03T10:22:20.048+0000] {task_command.py:467} INFO - Running <TaskInstance: fraud_detection_training.execute_training manual__2025-08-03T10:22:14.002760+00:00 [running]> on host b2485020a6c7
[2025-08-03T10:22:20.131+0000] {taskinstance.py:3134} INFO - Exporting env vars: AIRFLOW_CTX_DAG_OWNER='kanewyp' AIRFLOW_CTX_DAG_ID='fraud_detection_training' AIRFLOW_CTX_TASK_ID='execute_training' AIRFLOW_CTX_EXECUTION_DATE='2025-08-03T10:22:14.002760+00:00' AIRFLOW_CTX_TRY_NUMBER='1' AIRFLOW_CTX_DAG_RUN_ID='manual__2025-08-03T10:22:14.002760+00:00'
[2025-08-03T10:22:20.132+0000] {taskinstance.py:732} INFO - ::endgroup::
[2025-08-03T10:22:25.382+0000] {fraud_detection_training_dag.py:22} INFO - Initializing Fraud Detection Training
[2025-08-03T10:22:25.390+0000] {fraud_detection_training.py:64} INFO - Configuration loaded successfully
[2025-08-03T10:22:25.901+0000] {fraud_detection_training.py:90} INFO - Connected to MinIO. Available buckets: mlflow
[2025-08-03T10:22:26.296+0000] {fraud_detection_training.py:184} INFO - Starting model training process...
[2025-08-03T10:22:26.296+0000] {fraud_detection_training.py:106} INFO - Reading data from Kafka topic: transactions
[2025-08-03T10:22:26.455+0000] {conn.py:396} INFO - <BrokerConnection client_id=kafka-python-2.2.15, node_id=bootstrap-0 host=pkc-ldvj1.ap-southeast-2.aws.confluent.cloud:9092 <connecting> [IPv4 ('13.237.124.130', 9092)]>: connecting to pkc-ldvj1.ap-southeast-2.aws.confluent.cloud:9092 [('13.237.124.130', 9092) IPv4]
[2025-08-03T10:22:26.503+0000] {conn.py:497} INFO - <BrokerConnection client_id=kafka-python-2.2.15, node_id=bootstrap-0 host=pkc-ldvj1.ap-southeast-2.aws.confluent.cloud:9092 <handshake> [IPv4 ('13.237.124.130', 9092)]>: Loading system default SSL CAs from ('/usr/lib/ssl/cert.pem', '/usr/lib/ssl/certs', 'SSL_CERT_FILE', '/usr/lib/ssl/cert.pem', 'SSL_CERT_DIR', '/usr/lib/ssl/certs')
[2025-08-03T10:22:26.655+0000] {conn.py:618} INFO - <BrokerConnection client_id=kafka-python-2.2.15, node_id=bootstrap-0 host=pkc-ldvj1.ap-southeast-2.aws.confluent.cloud:9092 <checking_api_versions_recv> [IPv4 ('13.237.124.130', 9092)]>: Broker version identified as 2.6
[2025-08-03T10:22:26.821+0000] {conn.py:822} INFO - <BrokerConnection client_id=kafka-python-2.2.15, node_id=bootstrap-0 host=pkc-ldvj1.ap-southeast-2.aws.confluent.cloud:9092 <authenticating> [IPv4 ('13.237.124.130', 9092)]>: Authenticated as KQIWVOLDBVJZDLTP via SASL / Plain
[2025-08-03T10:22:26.822+0000] {conn.py:467} INFO - <BrokerConnection client_id=kafka-python-2.2.15, node_id=bootstrap-0 host=pkc-ldvj1.ap-southeast-2.aws.confluent.cloud:9092 <connected> [IPv4 ('13.237.124.130', 9092)]>: Connection complete.
[2025-08-03T10:22:26.823+0000] {consumer.py:120} WARNING - group_id is None: disabling auto-commit.
[2025-08-03T10:22:26.823+0000] {subscription_state.py:181} INFO - Updating subscribed topics to: ('transactions',)
[2025-08-03T10:22:26.872+0000] {subscription_state.py:254} INFO - Updated partition assignment: [('transactions', 0)]
[2025-08-03T10:22:26.940+0000] {conn.py:396} INFO - <BrokerConnection client_id=kafka-python-2.2.15, node_id=0 host=b0-pkc-ldvj1.ap-southeast-2.aws.confluent.cloud:9092 <connecting> [IPv4 ('3.24.104.123', 9092)]>: connecting to b0-pkc-ldvj1.ap-southeast-2.aws.confluent.cloud:9092 [('3.24.104.123', 9092) IPv4]
[2025-08-03T10:22:26.975+0000] {conn.py:497} INFO - <BrokerConnection client_id=kafka-python-2.2.15, node_id=0 host=b0-pkc-ldvj1.ap-southeast-2.aws.confluent.cloud:9092 <handshake> [IPv4 ('3.24.104.123', 9092)]>: Loading system default SSL CAs from ('/usr/lib/ssl/cert.pem', '/usr/lib/ssl/certs', 'SSL_CERT_FILE', '/usr/lib/ssl/cert.pem', 'SSL_CERT_DIR', '/usr/lib/ssl/certs')
[2025-08-03T10:22:27.219+0000] {conn.py:822} INFO - <BrokerConnection client_id=kafka-python-2.2.15, node_id=0 host=b0-pkc-ldvj1.ap-southeast-2.aws.confluent.cloud:9092 <authenticating> [IPv4 ('3.24.104.123', 9092)]>: Authenticated as KQIWVOLDBVJZDLTP via SASL / Plain
[2025-08-03T10:22:27.220+0000] {conn.py:467} INFO - <BrokerConnection client_id=kafka-python-2.2.15, node_id=0 host=b0-pkc-ldvj1.ap-southeast-2.aws.confluent.cloud:9092 <connected> [IPv4 ('3.24.104.123', 9092)]>: Connection complete.
[2025-08-03T10:22:27.220+0000] {conn.py:945} INFO - <BrokerConnection client_id=kafka-python-2.2.15, node_id=bootstrap-0 host=pkc-ldvj1.ap-southeast-2.aws.confluent.cloud:9092 <connected> [IPv4 ('13.237.124.130', 9092)]>: Closing connection. 
[2025-08-03T10:22:27.257+0000] {fetcher.py:418} INFO - Resetting offset for partition ('transactions', 0) to offset 0.
[2025-08-03T10:22:47.573+0000] {conn.py:945} INFO - <BrokerConnection client_id=kafka-python-2.2.15, node_id=0 host=b0-pkc-ldvj1.ap-southeast-2.aws.confluent.cloud:9092 <connected> [IPv4 ('3.24.104.123', 9092)]>: Closing connection. 
[2025-08-03T10:22:47.619+0000] {fetcher.py:786} INFO - Fetch to node 0 failed: Cancelled: <BrokerConnection client_id=kafka-python-2.2.15, node_id=0 host=b0-pkc-ldvj1.ap-southeast-2.aws.confluent.cloud:9092 <connected> [IPv4 ('3.24.104.123', 9092)]>
[2025-08-03T10:22:47.997+0000] {fraud_detection_training.py:133} INFO - Received 99372 records from Kafka with fraud rate: 0.73%
[2025-08-03T10:22:56.916+0000] {fraud_detection_training.py:263} INFO - Starting hyperparameter tuning...
[2025-08-03T10:27:28.711+0000] {job.py:229} INFO - Heartbeat recovered after 17.23 seconds
[2025-08-03T11:01:10.713+0000] {job.py:229} INFO - Heartbeat recovered after 1829.20 seconds
[2025-08-03T11:21:48.265+0000] {job.py:229} INFO - Heartbeat recovered after 1237.58 seconds
[2025-08-03T11:22:59.898+0000] {job.py:229} INFO - Heartbeat recovered after 18.71 seconds
[2025-08-03T11:23:37.058+0000] {job.py:229} INFO - Heartbeat recovered after 16.51 seconds
[2025-08-03T11:26:15.855+0000] {job.py:239} ERROR - Job heartbeat failed with error
Traceback (most recent call last):
  File "/home/airflow/.local/lib/python3.12/site-packages/sqlalchemy/engine/base.py", line 3371, in _wrap_pool_connect
    return fn()
           ^^^^
  File "/home/airflow/.local/lib/python3.12/site-packages/sqlalchemy/pool/base.py", line 327, in connect
    return _ConnectionFairy._checkout(self)
           ^^^^^^^^^^^^^^^^^^^^^^^^^^^^^^^^
  File "/home/airflow/.local/lib/python3.12/site-packages/sqlalchemy/pool/base.py", line 894, in _checkout
    fairy = _ConnectionRecord.checkout(pool)
            ^^^^^^^^^^^^^^^^^^^^^^^^^^^^^^^^
  File "/home/airflow/.local/lib/python3.12/site-packages/sqlalchemy/pool/base.py", line 493, in checkout
    rec = pool._do_get()
          ^^^^^^^^^^^^^^
  File "/home/airflow/.local/lib/python3.12/site-packages/sqlalchemy/pool/impl.py", line 256, in _do_get
    return self._create_connection()
           ^^^^^^^^^^^^^^^^^^^^^^^^^
  File "/home/airflow/.local/lib/python3.12/site-packages/sqlalchemy/pool/base.py", line 273, in _create_connection
    return _ConnectionRecord(self)
           ^^^^^^^^^^^^^^^^^^^^^^^
  File "/home/airflow/.local/lib/python3.12/site-packages/sqlalchemy/pool/base.py", line 388, in __init__
    self.__connect()
  File "/home/airflow/.local/lib/python3.12/site-packages/sqlalchemy/pool/base.py", line 690, in __connect
    with util.safe_reraise():
         ^^^^^^^^^^^^^^^^^^^
  File "/home/airflow/.local/lib/python3.12/site-packages/sqlalchemy/util/langhelpers.py", line 70, in __exit__
    compat.raise_(
  File "/home/airflow/.local/lib/python3.12/site-packages/sqlalchemy/util/compat.py", line 211, in raise_
    raise exception
  File "/home/airflow/.local/lib/python3.12/site-packages/sqlalchemy/pool/base.py", line 686, in __connect
    self.dbapi_connection = connection = pool._invoke_creator(self)
                                         ^^^^^^^^^^^^^^^^^^^^^^^^^^
  File "/home/airflow/.local/lib/python3.12/site-packages/sqlalchemy/engine/create.py", line 574, in connect
    return dialect.connect(*cargs, **cparams)
           ^^^^^^^^^^^^^^^^^^^^^^^^^^^^^^^^^^
  File "/home/airflow/.local/lib/python3.12/site-packages/sqlalchemy/engine/default.py", line 598, in connect
    return self.dbapi.connect(*cargs, **cparams)
           ^^^^^^^^^^^^^^^^^^^^^^^^^^^^^^^^^^^^^
  File "/home/airflow/.local/lib/python3.12/site-packages/psycopg2/__init__.py", line 122, in connect
    conn = _connect(dsn, connection_factory=connection_factory, **kwasync)
           ^^^^^^^^^^^^^^^^^^^^^^^^^^^^^^^^^^^^^^^^^^^^^^^^^^^^^^^^^^^^^^^
psycopg2.OperationalError: could not translate host name "postgres" to address: Temporary failure in name resolution


The above exception was the direct cause of the following exception:

Traceback (most recent call last):
  File "/home/airflow/.local/lib/python3.12/site-packages/airflow/jobs/job.py", line 207, in heartbeat
    self._merge_from(Job._fetch_from_db(self, session))
                     ^^^^^^^^^^^^^^^^^^^^^^^^^^^^^^^^^
  File "/home/airflow/.local/lib/python3.12/site-packages/airflow/api_internal/internal_api_call.py", line 166, in wrapper
    return func(*args, **kwargs)
           ^^^^^^^^^^^^^^^^^^^^^
  File "/home/airflow/.local/lib/python3.12/site-packages/airflow/utils/session.py", line 94, in wrapper
    return func(*args, **kwargs)
           ^^^^^^^^^^^^^^^^^^^^^
  File "/home/airflow/.local/lib/python3.12/site-packages/airflow/utils/retries.py", line 93, in wrapped_function
    for attempt in run_with_db_retries(max_retries=retries, logger=logger, **retry_kwargs):
                   ^^^^^^^^^^^^^^^^^^^^^^^^^^^^^^^^^^^^^^^^^^^^^^^^^^^^^^^^^^^^^^^^^^^^^^^
  File "/home/airflow/.local/lib/python3.12/site-packages/tenacity/__init__.py", line 443, in __iter__
    do = self.iter(retry_state=retry_state)
         ^^^^^^^^^^^^^^^^^^^^^^^^^^^^^^^^^^
  File "/home/airflow/.local/lib/python3.12/site-packages/tenacity/__init__.py", line 376, in iter
    result = action(retry_state)
             ^^^^^^^^^^^^^^^^^^^
  File "/home/airflow/.local/lib/python3.12/site-packages/tenacity/__init__.py", line 418, in exc_check
    raise retry_exc.reraise()
          ^^^^^^^^^^^^^^^^^^^
  File "/home/airflow/.local/lib/python3.12/site-packages/tenacity/__init__.py", line 185, in reraise
    raise self.last_attempt.result()
          ^^^^^^^^^^^^^^^^^^^^^^^^^^
  File "/usr/local/lib/python3.12/concurrent/futures/_base.py", line 449, in result
    return self.__get_result()
           ^^^^^^^^^^^^^^^^^^^
  File "/usr/local/lib/python3.12/concurrent/futures/_base.py", line 401, in __get_result
    raise self._exception
  File "/home/airflow/.local/lib/python3.12/site-packages/airflow/utils/retries.py", line 102, in wrapped_function
    return func(*args, **kwargs)
           ^^^^^^^^^^^^^^^^^^^^^
  File "/home/airflow/.local/lib/python3.12/site-packages/airflow/jobs/job.py", line 335, in _fetch_from_db
    session.merge(job)
  File "/home/airflow/.local/lib/python3.12/site-packages/sqlalchemy/orm/session.py", line 3056, in merge
    return self._merge(
           ^^^^^^^^^^^^
  File "/home/airflow/.local/lib/python3.12/site-packages/sqlalchemy/orm/session.py", line 3136, in _merge
    merged = self.get(
             ^^^^^^^^^
  File "/home/airflow/.local/lib/python3.12/site-packages/sqlalchemy/orm/session.py", line 2853, in get
    return self._get_impl(
           ^^^^^^^^^^^^^^^
  File "/home/airflow/.local/lib/python3.12/site-packages/sqlalchemy/orm/session.py", line 2975, in _get_impl
    return db_load_fn(
           ^^^^^^^^^^^
  File "/home/airflow/.local/lib/python3.12/site-packages/sqlalchemy/orm/loading.py", line 530, in load_on_pk_identity
    session.execute(
  File "/home/airflow/.local/lib/python3.12/site-packages/sqlalchemy/orm/session.py", line 1716, in execute
    conn = self._connection_for_bind(bind)
           ^^^^^^^^^^^^^^^^^^^^^^^^^^^^^^^
  File "/home/airflow/.local/lib/python3.12/site-packages/sqlalchemy/orm/session.py", line 1555, in _connection_for_bind
    return self._transaction._connection_for_bind(
           ^^^^^^^^^^^^^^^^^^^^^^^^^^^^^^^^^^^^^^^
  File "/home/airflow/.local/lib/python3.12/site-packages/sqlalchemy/orm/session.py", line 750, in _connection_for_bind
    conn = bind.connect()
           ^^^^^^^^^^^^^^
  File "/home/airflow/.local/lib/python3.12/site-packages/sqlalchemy/future/engine.py", line 412, in connect
    return super(Engine, self).connect()
           ^^^^^^^^^^^^^^^^^^^^^^^^^^^^^
  File "/home/airflow/.local/lib/python3.12/site-packages/sqlalchemy/engine/base.py", line 3325, in connect
    return self._connection_cls(self, close_with_result=close_with_result)
           ^^^^^^^^^^^^^^^^^^^^^^^^^^^^^^^^^^^^^^^^^^^^^^^^^^^^^^^^^^^^^^^
  File "/home/airflow/.local/lib/python3.12/site-packages/sqlalchemy/engine/base.py", line 96, in __init__
    else engine.raw_connection()
         ^^^^^^^^^^^^^^^^^^^^^^^
  File "/home/airflow/.local/lib/python3.12/site-packages/sqlalchemy/engine/base.py", line 3404, in raw_connection
    return self._wrap_pool_connect(self.pool.connect, _connection)
           ^^^^^^^^^^^^^^^^^^^^^^^^^^^^^^^^^^^^^^^^^^^^^^^^^^^^^^^
  File "/home/airflow/.local/lib/python3.12/site-packages/sqlalchemy/engine/base.py", line 3374, in _wrap_pool_connect
    Connection._handle_dbapi_exception_noconnection(
  File "/home/airflow/.local/lib/python3.12/site-packages/sqlalchemy/engine/base.py", line 2208, in _handle_dbapi_exception_noconnection
    util.raise_(
  File "/home/airflow/.local/lib/python3.12/site-packages/sqlalchemy/util/compat.py", line 211, in raise_
    raise exception
  File "/home/airflow/.local/lib/python3.12/site-packages/sqlalchemy/engine/base.py", line 3371, in _wrap_pool_connect
    return fn()
           ^^^^
  File "/home/airflow/.local/lib/python3.12/site-packages/sqlalchemy/pool/base.py", line 327, in connect
    return _ConnectionFairy._checkout(self)
           ^^^^^^^^^^^^^^^^^^^^^^^^^^^^^^^^
  File "/home/airflow/.local/lib/python3.12/site-packages/sqlalchemy/pool/base.py", line 894, in _checkout
    fairy = _ConnectionRecord.checkout(pool)
            ^^^^^^^^^^^^^^^^^^^^^^^^^^^^^^^^
  File "/home/airflow/.local/lib/python3.12/site-packages/sqlalchemy/pool/base.py", line 493, in checkout
    rec = pool._do_get()
          ^^^^^^^^^^^^^^
  File "/home/airflow/.local/lib/python3.12/site-packages/sqlalchemy/pool/impl.py", line 256, in _do_get
    return self._create_connection()
           ^^^^^^^^^^^^^^^^^^^^^^^^^
  File "/home/airflow/.local/lib/python3.12/site-packages/sqlalchemy/pool/base.py", line 273, in _create_connection
    return _ConnectionRecord(self)
           ^^^^^^^^^^^^^^^^^^^^^^^
  File "/home/airflow/.local/lib/python3.12/site-packages/sqlalchemy/pool/base.py", line 388, in __init__
    self.__connect()
  File "/home/airflow/.local/lib/python3.12/site-packages/sqlalchemy/pool/base.py", line 690, in __connect
    with util.safe_reraise():
         ^^^^^^^^^^^^^^^^^^^
  File "/home/airflow/.local/lib/python3.12/site-packages/sqlalchemy/util/langhelpers.py", line 70, in __exit__
    compat.raise_(
  File "/home/airflow/.local/lib/python3.12/site-packages/sqlalchemy/util/compat.py", line 211, in raise_
    raise exception
  File "/home/airflow/.local/lib/python3.12/site-packages/sqlalchemy/pool/base.py", line 686, in __connect
    self.dbapi_connection = connection = pool._invoke_creator(self)
                                         ^^^^^^^^^^^^^^^^^^^^^^^^^^
  File "/home/airflow/.local/lib/python3.12/site-packages/sqlalchemy/engine/create.py", line 574, in connect
    return dialect.connect(*cargs, **cparams)
           ^^^^^^^^^^^^^^^^^^^^^^^^^^^^^^^^^^
  File "/home/airflow/.local/lib/python3.12/site-packages/sqlalchemy/engine/default.py", line 598, in connect
    return self.dbapi.connect(*cargs, **cparams)
           ^^^^^^^^^^^^^^^^^^^^^^^^^^^^^^^^^^^^^
  File "/home/airflow/.local/lib/python3.12/site-packages/psycopg2/__init__.py", line 122, in connect
    conn = _connect(dsn, connection_factory=connection_factory, **kwasync)
           ^^^^^^^^^^^^^^^^^^^^^^^^^^^^^^^^^^^^^^^^^^^^^^^^^^^^^^^^^^^^^^^
sqlalchemy.exc.OperationalError: (psycopg2.OperationalError) could not translate host name "postgres" to address: Temporary failure in name resolution

(Background on this error at: https://sqlalche.me/e/14/e3q8)
[2025-08-03T11:26:22.119+0000] {job.py:254} ERROR - Job heartbeat failed with error. Scheduler is in unhealthy state
[2025-08-03T11:26:35.172+0000] {job.py:229} INFO - Heartbeat recovered after 104.60 seconds
[2025-08-03T11:31:55.059+0000] {job.py:229} INFO - Heartbeat recovered after 12.18 seconds
