[2025-07-28T00:48:23.280+0000] {local_task_job_runner.py:123} INFO - ::group::Pre task execution logs
[2025-07-28T00:48:23.373+0000] {taskinstance.py:2614} INFO - Dependencies all met for dep_context=non-requeueable deps ti=<TaskInstance: fraud_detection_training.execute_training scheduled__2025-07-27T00:18:00+00:00 [queued]>
[2025-07-28T00:48:23.426+0000] {taskinstance.py:2614} INFO - Dependencies all met for dep_context=requeueable deps ti=<TaskInstance: fraud_detection_training.execute_training scheduled__2025-07-27T00:18:00+00:00 [queued]>
[2025-07-28T00:48:23.427+0000] {taskinstance.py:2867} INFO - Starting attempt 2 of 1
[2025-07-28T00:48:23.479+0000] {taskinstance.py:2890} INFO - Executing <Task(PythonOperator): execute_training> on 2025-07-27 00:18:00+00:00
[2025-07-28T00:48:23.518+0000] {warnings.py:112} WARNING - /home/***/.local/lib/python3.12/site-packages/***/task/task_runner/standard_task_runner.py:70: DeprecationWarning: This process (pid=1437) is multi-threaded, use of fork() may lead to deadlocks in the child.
  pid = os.fork()

[2025-07-28T00:48:23.528+0000] {standard_task_runner.py:72} INFO - Started process 1438 to run task
[2025-07-28T00:48:23.521+0000] {standard_task_runner.py:104} INFO - Running: ['***', 'tasks', 'run', 'fraud_detection_training', 'execute_training', 'scheduled__2025-07-27T00:18:00+00:00', '--job-id', '84', '--raw', '--subdir', 'DAGS_FOLDER/fraud_detection_training_dag.py', '--cfg-path', '/tmp/tmpiab0itkw']
[2025-07-28T00:48:23.532+0000] {standard_task_runner.py:105} INFO - Job 84: Subtask execute_training
[2025-07-28T00:48:23.687+0000] {task_command.py:467} INFO - Running <TaskInstance: fraud_detection_training.execute_training scheduled__2025-07-27T00:18:00+00:00 [running]> on host c0f7bf91f6c3
[2025-07-28T00:48:23.928+0000] {taskinstance.py:3134} INFO - Exporting env vars: AIRFLOW_CTX_DAG_OWNER='kanewyp' AIRFLOW_CTX_DAG_ID='fraud_detection_training' AIRFLOW_CTX_TASK_ID='execute_training' AIRFLOW_CTX_EXECUTION_DATE='2025-07-27T00:18:00+00:00' AIRFLOW_CTX_TRY_NUMBER='2' AIRFLOW_CTX_DAG_RUN_ID='scheduled__2025-07-27T00:18:00+00:00'
[2025-07-28T00:48:23.930+0000] {taskinstance.py:732} INFO - ::endgroup::
[2025-07-28T00:48:34.425+0000] {fraud_detection_training_dag.py:22} INFO - Initializing Fraud Detection Training
[2025-07-28T00:48:34.452+0000] {fraud_detection_training.py:62} INFO - Configuration loaded successfully
[2025-07-28T00:48:36.629+0000] {fraud_detection_training.py:88} INFO - Connected to MinIO. Available buckets: mlflow
[2025-07-28T00:48:37.094+0000] {fraud_detection_training.py:182} INFO - Starting model training process...
[2025-07-28T00:48:37.095+0000] {fraud_detection_training.py:104} INFO - Reading data from Kafka topic: fraud_detection
[2025-07-28T00:48:37.184+0000] {conn.py:396} INFO - <BrokerConnection client_id=kafka-python-2.2.15, node_id=bootstrap-0 host=pkc-ldvj1.ap-southeast-2.aws.confluent.cloud:9092 <connecting> [IPv4 ('52.64.27.176', 9092)]>: connecting to pkc-ldvj1.ap-southeast-2.aws.confluent.cloud:9092 [('52.64.27.176', 9092) IPv4]
[2025-07-28T00:48:37.226+0000] {conn.py:497} INFO - <BrokerConnection client_id=kafka-python-2.2.15, node_id=bootstrap-0 host=pkc-ldvj1.ap-southeast-2.aws.confluent.cloud:9092 <handshake> [IPv4 ('52.64.27.176', 9092)]>: Loading system default SSL CAs from ('/usr/lib/ssl/cert.pem', '/usr/lib/ssl/certs', 'SSL_CERT_FILE', '/usr/lib/ssl/cert.pem', 'SSL_CERT_DIR', '/usr/lib/ssl/certs')
[2025-07-28T00:48:37.389+0000] {conn.py:618} INFO - <BrokerConnection client_id=kafka-python-2.2.15, node_id=bootstrap-0 host=pkc-ldvj1.ap-southeast-2.aws.confluent.cloud:9092 <checking_api_versions_recv> [IPv4 ('52.64.27.176', 9092)]>: Broker version identified as 2.6
[2025-07-28T00:48:37.580+0000] {conn.py:822} INFO - <BrokerConnection client_id=kafka-python-2.2.15, node_id=bootstrap-0 host=pkc-ldvj1.ap-southeast-2.aws.confluent.cloud:9092 <authenticating> [IPv4 ('52.64.27.176', 9092)]>: Authenticated as KQIWVOLDBVJZDLTP via SASL / Plain
[2025-07-28T00:48:37.582+0000] {conn.py:467} INFO - <BrokerConnection client_id=kafka-python-2.2.15, node_id=bootstrap-0 host=pkc-ldvj1.ap-southeast-2.aws.confluent.cloud:9092 <connected> [IPv4 ('52.64.27.176', 9092)]>: Connection complete.
[2025-07-28T00:48:37.584+0000] {consumer.py:120} WARNING - group_id is None: disabling auto-commit.
[2025-07-28T00:48:37.585+0000] {subscription_state.py:181} INFO - Updating subscribed topics to: ('fraud_detection',)
[2025-07-28T00:48:37.630+0000] {subscription_state.py:254} INFO - Updated partition assignment: [('fraud_detection', 0), ('fraud_detection', 1), ('fraud_detection', 2), ('fraud_detection', 3), ('fraud_detection', 4), ('fraud_detection', 5)]
[2025-07-28T00:48:37.709+0000] {conn.py:396} INFO - <BrokerConnection client_id=kafka-python-2.2.15, node_id=0 host=b0-pkc-ldvj1.ap-southeast-2.aws.confluent.cloud:9092 <connecting> [IPv4 ('3.24.101.143', 9092)]>: connecting to b0-pkc-ldvj1.ap-southeast-2.aws.confluent.cloud:9092 [('3.24.101.143', 9092) IPv4]
[2025-07-28T00:48:37.783+0000] {conn.py:396} INFO - <BrokerConnection client_id=kafka-python-2.2.15, node_id=1 host=b1-pkc-ldvj1.ap-southeast-2.aws.confluent.cloud:9092 <connecting> [IPv4 ('13.238.192.73', 9092)]>: connecting to b1-pkc-ldvj1.ap-southeast-2.aws.confluent.cloud:9092 [('13.238.192.73', 9092) IPv4]
[2025-07-28T00:48:37.868+0000] {conn.py:396} INFO - <BrokerConnection client_id=kafka-python-2.2.15, node_id=2 host=b2-pkc-ldvj1.ap-southeast-2.aws.confluent.cloud:9092 <connecting> [IPv4 ('52.63.61.170', 9092)]>: connecting to b2-pkc-ldvj1.ap-southeast-2.aws.confluent.cloud:9092 [('52.63.61.170', 9092) IPv4]
[2025-07-28T00:48:37.942+0000] {conn.py:396} INFO - <BrokerConnection client_id=kafka-python-2.2.15, node_id=3 host=b3-pkc-ldvj1.ap-southeast-2.aws.confluent.cloud:9092 <connecting> [IPv4 ('3.106.149.208', 9092)]>: connecting to b3-pkc-ldvj1.ap-southeast-2.aws.confluent.cloud:9092 [('3.106.149.208', 9092) IPv4]
[2025-07-28T00:48:38.005+0000] {conn.py:396} INFO - <BrokerConnection client_id=kafka-python-2.2.15, node_id=4 host=b4-pkc-ldvj1.ap-southeast-2.aws.confluent.cloud:9092 <connecting> [IPv4 ('13.210.104.107', 9092)]>: connecting to b4-pkc-ldvj1.ap-southeast-2.aws.confluent.cloud:9092 [('13.210.104.107', 9092) IPv4]
[2025-07-28T00:48:38.107+0000] {conn.py:396} INFO - <BrokerConnection client_id=kafka-python-2.2.15, node_id=5 host=b5-pkc-ldvj1.ap-southeast-2.aws.confluent.cloud:9092 <connecting> [IPv4 ('13.237.226.149', 9092)]>: connecting to b5-pkc-ldvj1.ap-southeast-2.aws.confluent.cloud:9092 [('13.237.226.149', 9092) IPv4]
[2025-07-28T00:48:38.109+0000] {conn.py:497} INFO - <BrokerConnection client_id=kafka-python-2.2.15, node_id=0 host=b0-pkc-ldvj1.ap-southeast-2.aws.confluent.cloud:9092 <handshake> [IPv4 ('3.24.101.143', 9092)]>: Loading system default SSL CAs from ('/usr/lib/ssl/cert.pem', '/usr/lib/ssl/certs', 'SSL_CERT_FILE', '/usr/lib/ssl/cert.pem', 'SSL_CERT_DIR', '/usr/lib/ssl/certs')
[2025-07-28T00:48:38.144+0000] {conn.py:497} INFO - <BrokerConnection client_id=kafka-python-2.2.15, node_id=1 host=b1-pkc-ldvj1.ap-southeast-2.aws.confluent.cloud:9092 <handshake> [IPv4 ('13.238.192.73', 9092)]>: Loading system default SSL CAs from ('/usr/lib/ssl/cert.pem', '/usr/lib/ssl/certs', 'SSL_CERT_FILE', '/usr/lib/ssl/cert.pem', 'SSL_CERT_DIR', '/usr/lib/ssl/certs')
[2025-07-28T00:48:38.180+0000] {conn.py:497} INFO - <BrokerConnection client_id=kafka-python-2.2.15, node_id=2 host=b2-pkc-ldvj1.ap-southeast-2.aws.confluent.cloud:9092 <handshake> [IPv4 ('52.63.61.170', 9092)]>: Loading system default SSL CAs from ('/usr/lib/ssl/cert.pem', '/usr/lib/ssl/certs', 'SSL_CERT_FILE', '/usr/lib/ssl/cert.pem', 'SSL_CERT_DIR', '/usr/lib/ssl/certs')
[2025-07-28T00:48:38.218+0000] {conn.py:497} INFO - <BrokerConnection client_id=kafka-python-2.2.15, node_id=3 host=b3-pkc-ldvj1.ap-southeast-2.aws.confluent.cloud:9092 <handshake> [IPv4 ('3.106.149.208', 9092)]>: Loading system default SSL CAs from ('/usr/lib/ssl/cert.pem', '/usr/lib/ssl/certs', 'SSL_CERT_FILE', '/usr/lib/ssl/cert.pem', 'SSL_CERT_DIR', '/usr/lib/ssl/certs')
[2025-07-28T00:48:38.259+0000] {conn.py:497} INFO - <BrokerConnection client_id=kafka-python-2.2.15, node_id=4 host=b4-pkc-ldvj1.ap-southeast-2.aws.confluent.cloud:9092 <handshake> [IPv4 ('13.210.104.107', 9092)]>: Loading system default SSL CAs from ('/usr/lib/ssl/cert.pem', '/usr/lib/ssl/certs', 'SSL_CERT_FILE', '/usr/lib/ssl/cert.pem', 'SSL_CERT_DIR', '/usr/lib/ssl/certs')
[2025-07-28T00:48:38.311+0000] {conn.py:497} INFO - <BrokerConnection client_id=kafka-python-2.2.15, node_id=5 host=b5-pkc-ldvj1.ap-southeast-2.aws.confluent.cloud:9092 <handshake> [IPv4 ('13.237.226.149', 9092)]>: Loading system default SSL CAs from ('/usr/lib/ssl/cert.pem', '/usr/lib/ssl/certs', 'SSL_CERT_FILE', '/usr/lib/ssl/cert.pem', 'SSL_CERT_DIR', '/usr/lib/ssl/certs')
[2025-07-28T00:48:38.550+0000] {conn.py:822} INFO - <BrokerConnection client_id=kafka-python-2.2.15, node_id=0 host=b0-pkc-ldvj1.ap-southeast-2.aws.confluent.cloud:9092 <authenticating> [IPv4 ('3.24.101.143', 9092)]>: Authenticated as KQIWVOLDBVJZDLTP via SASL / Plain
[2025-07-28T00:48:38.551+0000] {conn.py:467} INFO - <BrokerConnection client_id=kafka-python-2.2.15, node_id=0 host=b0-pkc-ldvj1.ap-southeast-2.aws.confluent.cloud:9092 <connected> [IPv4 ('3.24.101.143', 9092)]>: Connection complete.
[2025-07-28T00:48:38.551+0000] {conn.py:945} INFO - <BrokerConnection client_id=kafka-python-2.2.15, node_id=bootstrap-0 host=pkc-ldvj1.ap-southeast-2.aws.confluent.cloud:9092 <connected> [IPv4 ('52.64.27.176', 9092)]>: Closing connection. 
[2025-07-28T01:20:04.066+0000] {conn.py:822} INFO - <BrokerConnection client_id=kafka-python-2.2.15, node_id=2 host=b2-pkc-ldvj1.ap-southeast-2.aws.confluent.cloud:9092 <authenticating> [IPv4 ('52.63.61.170', 9092)]>: Authenticated as KQIWVOLDBVJZDLTP via SASL / Plain
[2025-07-28T01:20:04.145+0000] {conn.py:1163} ERROR - <BrokerConnection client_id=kafka-python-2.2.15, node_id=2 host=b2-pkc-ldvj1.ap-southeast-2.aws.confluent.cloud:9092 <authenticating> [IPv4 ('52.63.61.170', 9092)]>: socket disconnected
[2025-07-28T01:20:04.146+0000] {conn.py:945} ERROR - <BrokerConnection client_id=kafka-python-2.2.15, node_id=2 host=b2-pkc-ldvj1.ap-southeast-2.aws.confluent.cloud:9092 <authenticating> [IPv4 ('52.63.61.170', 9092)]>: Closing connection. KafkaConnectionError: socket disconnected
[2025-07-28T01:20:04.159+0000] {conn.py:783} ERROR - <BrokerConnection client_id=kafka-python-2.2.15, node_id=3 host=b3-pkc-ldvj1.ap-southeast-2.aws.confluent.cloud:9092 <authenticating> [IPv4 ('3.106.149.208', 9092)]>: Error receiving sasl auth bytes from server
Traceback (most recent call last):
  File "/home/airflow/.local/lib/python3.12/site-packages/kafka/conn.py", line 779, in _recv_sasl_authenticate
    data = self._recv_bytes_blocking(4)
           ^^^^^^^^^^^^^^^^^^^^^^^^^^^^
  File "/home/airflow/.local/lib/python3.12/site-packages/kafka/conn.py", line 751, in _recv_bytes_blocking
    raise ConnectionError('Connection reset during recv')
ConnectionError: Connection reset during recv
[2025-07-28T01:20:04.192+0000] {conn.py:945} ERROR - <BrokerConnection client_id=kafka-python-2.2.15, node_id=3 host=b3-pkc-ldvj1.ap-southeast-2.aws.confluent.cloud:9092 <authenticating> [IPv4 ('3.106.149.208', 9092)]>: Closing connection. KafkaConnectionError: <BrokerConnection client_id=kafka-python-2.2.15, node_id=3 host=b3-pkc-ldvj1.ap-southeast-2.aws.confluent.cloud:9092 <authenticating> [IPv4 ('3.106.149.208', 9092)]>: Connection reset during recv
[2025-07-28T01:20:04.196+0000] {conn.py:783} ERROR - <BrokerConnection client_id=kafka-python-2.2.15, node_id=1 host=b1-pkc-ldvj1.ap-southeast-2.aws.confluent.cloud:9092 <authenticating> [IPv4 ('13.238.192.73', 9092)]>: Error receiving sasl auth bytes from server
Traceback (most recent call last):
  File "/home/airflow/.local/lib/python3.12/site-packages/kafka/conn.py", line 779, in _recv_sasl_authenticate
    data = self._recv_bytes_blocking(4)
           ^^^^^^^^^^^^^^^^^^^^^^^^^^^^
  File "/home/airflow/.local/lib/python3.12/site-packages/kafka/conn.py", line 751, in _recv_bytes_blocking
    raise ConnectionError('Connection reset during recv')
ConnectionError: Connection reset during recv
[2025-07-28T01:20:04.209+0000] {conn.py:945} ERROR - <BrokerConnection client_id=kafka-python-2.2.15, node_id=1 host=b1-pkc-ldvj1.ap-southeast-2.aws.confluent.cloud:9092 <authenticating> [IPv4 ('13.238.192.73', 9092)]>: Closing connection. KafkaConnectionError: <BrokerConnection client_id=kafka-python-2.2.15, node_id=1 host=b1-pkc-ldvj1.ap-southeast-2.aws.confluent.cloud:9092 <authenticating> [IPv4 ('13.238.192.73', 9092)]>: Connection reset during recv
[2025-07-28T01:20:04.221+0000] {conn.py:945} INFO - <BrokerConnection client_id=kafka-python-2.2.15, node_id=0 host=b0-pkc-ldvj1.ap-southeast-2.aws.confluent.cloud:9092 <connected> [IPv4 ('3.24.101.143', 9092)]>: Closing connection. 
[2025-07-28T01:20:04.227+0000] {conn.py:945} INFO - <BrokerConnection client_id=kafka-python-2.2.15, node_id=4 host=b4-pkc-ldvj1.ap-southeast-2.aws.confluent.cloud:9092 <authenticating> [IPv4 ('13.210.104.107', 9092)]>: Closing connection. 
[2025-07-28T01:20:04.247+0000] {conn.py:945} INFO - <BrokerConnection client_id=kafka-python-2.2.15, node_id=5 host=b5-pkc-ldvj1.ap-southeast-2.aws.confluent.cloud:9092 <authenticating> [IPv4 ('13.237.226.149', 9092)]>: Closing connection. 
[2025-07-28T01:20:04.306+0000] {job.py:229} INFO - Heartbeat recovered after 1890.69 seconds
[2025-07-28T01:20:04.343+0000] {fraud_detection_training.py:135} ERROR - Failed to read data from Kafka: No message received from Kafka
Traceback (most recent call last):
  File "/opt/airflow/dags/fraud_detection_training.py", line 123, in _read_data_from_kafka
    raise ValueError('No message received from Kafka')
ValueError: No message received from Kafka
[2025-07-28T01:20:04.345+0000] {fraud_detection_training.py:337} ERROR - Training failed: No message received from Kafka
Traceback (most recent call last):
  File "/opt/airflow/dags/fraud_detection_training.py", line 185, in train_model
    df = self._read_data_from_kafka()
         ^^^^^^^^^^^^^^^^^^^^^^^^^^^^
  File "/opt/airflow/dags/fraud_detection_training.py", line 123, in _read_data_from_kafka
    raise ValueError('No message received from Kafka')
ValueError: No message received from Kafka
[2025-07-28T01:20:04.361+0000] {fraud_detection_training_dag.py:28} ERROR - Training failed: No message received from Kafka
Traceback (most recent call last):
  File "/opt/airflow/dags/fraud_detection_training_dag.py", line 24, in _train_model
    model, precision = trainer.train_model()
                       ^^^^^^^^^^^^^^^^^^^^^
  File "/opt/airflow/dags/fraud_detection_training.py", line 185, in train_model
    df = self._read_data_from_kafka()
         ^^^^^^^^^^^^^^^^^^^^^^^^^^^^
  File "/opt/airflow/dags/fraud_detection_training.py", line 123, in _read_data_from_kafka
    raise ValueError('No message received from Kafka')
ValueError: No message received from Kafka
[2025-07-28T01:20:04.485+0000] {taskinstance.py:3313} ERROR - Task failed with exception
Traceback (most recent call last):
  File "/opt/airflow/dags/fraud_detection_training_dag.py", line 24, in _train_model
    model, precision = trainer.train_model()
                       ^^^^^^^^^^^^^^^^^^^^^
  File "/opt/airflow/dags/fraud_detection_training.py", line 185, in train_model
    df = self._read_data_from_kafka()
         ^^^^^^^^^^^^^^^^^^^^^^^^^^^^
  File "/opt/airflow/dags/fraud_detection_training.py", line 123, in _read_data_from_kafka
    raise ValueError('No message received from Kafka')
ValueError: No message received from Kafka

During handling of the above exception, another exception occurred:

Traceback (most recent call last):
  File "/home/airflow/.local/lib/python3.12/site-packages/airflow/models/taskinstance.py", line 768, in _execute_task
    result = _execute_callable(context=context, **execute_callable_kwargs)
             ^^^^^^^^^^^^^^^^^^^^^^^^^^^^^^^^^^^^^^^^^^^^^^^^^^^^^^^^^^^^^
  File "/home/airflow/.local/lib/python3.12/site-packages/airflow/models/taskinstance.py", line 734, in _execute_callable
    return ExecutionCallableRunner(
           ^^^^^^^^^^^^^^^^^^^^^^^^
  File "/home/airflow/.local/lib/python3.12/site-packages/airflow/utils/operator_helpers.py", line 252, in run
    return self.func(*args, **kwargs)
           ^^^^^^^^^^^^^^^^^^^^^^^^^^
  File "/home/airflow/.local/lib/python3.12/site-packages/airflow/models/baseoperator.py", line 424, in wrapper
    return func(self, *args, **kwargs)
           ^^^^^^^^^^^^^^^^^^^^^^^^^^^
  File "/home/airflow/.local/lib/python3.12/site-packages/airflow/operators/python.py", line 238, in execute
    return_value = self.execute_callable()
                   ^^^^^^^^^^^^^^^^^^^^^^^
  File "/home/airflow/.local/lib/python3.12/site-packages/airflow/operators/python.py", line 256, in execute_callable
    return runner.run(*self.op_args, **self.op_kwargs)
           ^^^^^^^^^^^^^^^^^^^^^^^^^^^^^^^^^^^^^^^^^^^
  File "/home/airflow/.local/lib/python3.12/site-packages/airflow/utils/operator_helpers.py", line 252, in run
    return self.func(*args, **kwargs)
           ^^^^^^^^^^^^^^^^^^^^^^^^^^
  File "/opt/airflow/dags/fraud_detection_training_dag.py", line 29, in _train_model
    raise AirflowException(f"Model Training failed: {str(e)}")
airflow.exceptions.AirflowException: Model Training failed: No message received from Kafka
[2025-07-28T01:20:04.512+0000] {taskinstance.py:1226} INFO - Marking task as FAILED. dag_id=fraud_detection_training, task_id=execute_training, run_id=scheduled__2025-07-27T00:18:00+00:00, execution_date=20250727T001800, start_date=20250728T004823, end_date=20250728T012004
[2025-07-28T01:20:04.689+0000] {taskinstance.py:341} INFO - ::group::Post task execution logs
[2025-07-28T01:20:04.690+0000] {standard_task_runner.py:124} ERROR - Failed to execute job 84 for task execute_training (Model Training failed: No message received from Kafka; 1438)
Traceback (most recent call last):
  File "/opt/airflow/dags/fraud_detection_training_dag.py", line 24, in _train_model
    model, precision = trainer.train_model()
                       ^^^^^^^^^^^^^^^^^^^^^
  File "/opt/airflow/dags/fraud_detection_training.py", line 185, in train_model
    df = self._read_data_from_kafka()
         ^^^^^^^^^^^^^^^^^^^^^^^^^^^^
  File "/opt/airflow/dags/fraud_detection_training.py", line 123, in _read_data_from_kafka
    raise ValueError('No message received from Kafka')
ValueError: No message received from Kafka

During handling of the above exception, another exception occurred:

Traceback (most recent call last):
  File "/home/airflow/.local/lib/python3.12/site-packages/airflow/task/task_runner/standard_task_runner.py", line 117, in _start_by_fork
    ret = args.func(args, dag=self.dag)
          ^^^^^^^^^^^^^^^^^^^^^^^^^^^^^
  File "/home/airflow/.local/lib/python3.12/site-packages/airflow/cli/cli_config.py", line 49, in command
    return func(*args, **kwargs)
           ^^^^^^^^^^^^^^^^^^^^^
  File "/home/airflow/.local/lib/python3.12/site-packages/airflow/utils/cli.py", line 116, in wrapper
    return f(*args, **kwargs)
           ^^^^^^^^^^^^^^^^^^
  File "/home/airflow/.local/lib/python3.12/site-packages/airflow/cli/commands/task_command.py", line 483, in task_run
    task_return_code = _run_task_by_selected_method(args, _dag, ti)
                       ^^^^^^^^^^^^^^^^^^^^^^^^^^^^^^^^^^^^^^^^^^^^
  File "/home/airflow/.local/lib/python3.12/site-packages/airflow/cli/commands/task_command.py", line 256, in _run_task_by_selected_method
    return _run_raw_task(args, ti)
           ^^^^^^^^^^^^^^^^^^^^^^^
  File "/home/airflow/.local/lib/python3.12/site-packages/airflow/cli/commands/task_command.py", line 341, in _run_raw_task
    return ti._run_raw_task(
           ^^^^^^^^^^^^^^^^^
  File "/home/airflow/.local/lib/python3.12/site-packages/airflow/utils/session.py", line 97, in wrapper
    return func(*args, session=session, **kwargs)
           ^^^^^^^^^^^^^^^^^^^^^^^^^^^^^^^^^^^^^^
  File "/home/airflow/.local/lib/python3.12/site-packages/airflow/models/taskinstance.py", line 3006, in _run_raw_task
    return _run_raw_task(
           ^^^^^^^^^^^^^^
  File "/home/airflow/.local/lib/python3.12/site-packages/airflow/models/taskinstance.py", line 274, in _run_raw_task
    TaskInstance._execute_task_with_callbacks(
  File "/home/airflow/.local/lib/python3.12/site-packages/airflow/models/taskinstance.py", line 3161, in _execute_task_with_callbacks
    result = self._execute_task(context, task_orig)
             ^^^^^^^^^^^^^^^^^^^^^^^^^^^^^^^^^^^^^^
  File "/home/airflow/.local/lib/python3.12/site-packages/airflow/models/taskinstance.py", line 3185, in _execute_task
    return _execute_task(self, context, task_orig)
           ^^^^^^^^^^^^^^^^^^^^^^^^^^^^^^^^^^^^^^^
  File "/home/airflow/.local/lib/python3.12/site-packages/airflow/models/taskinstance.py", line 768, in _execute_task
    result = _execute_callable(context=context, **execute_callable_kwargs)
             ^^^^^^^^^^^^^^^^^^^^^^^^^^^^^^^^^^^^^^^^^^^^^^^^^^^^^^^^^^^^^
  File "/home/airflow/.local/lib/python3.12/site-packages/airflow/models/taskinstance.py", line 734, in _execute_callable
    return ExecutionCallableRunner(
           ^^^^^^^^^^^^^^^^^^^^^^^^
  File "/home/airflow/.local/lib/python3.12/site-packages/airflow/utils/operator_helpers.py", line 252, in run
    return self.func(*args, **kwargs)
           ^^^^^^^^^^^^^^^^^^^^^^^^^^
  File "/home/airflow/.local/lib/python3.12/site-packages/airflow/models/baseoperator.py", line 424, in wrapper
    return func(self, *args, **kwargs)
           ^^^^^^^^^^^^^^^^^^^^^^^^^^^
  File "/home/airflow/.local/lib/python3.12/site-packages/airflow/operators/python.py", line 238, in execute
    return_value = self.execute_callable()
                   ^^^^^^^^^^^^^^^^^^^^^^^
  File "/home/airflow/.local/lib/python3.12/site-packages/airflow/operators/python.py", line 256, in execute_callable
    return runner.run(*self.op_args, **self.op_kwargs)
           ^^^^^^^^^^^^^^^^^^^^^^^^^^^^^^^^^^^^^^^^^^^
  File "/home/airflow/.local/lib/python3.12/site-packages/airflow/utils/operator_helpers.py", line 252, in run
    return self.func(*args, **kwargs)
           ^^^^^^^^^^^^^^^^^^^^^^^^^^
  File "/opt/airflow/dags/fraud_detection_training_dag.py", line 29, in _train_model
    raise AirflowException(f"Model Training failed: {str(e)}")
airflow.exceptions.AirflowException: Model Training failed: No message received from Kafka
[2025-07-28T01:20:04.904+0000] {local_task_job_runner.py:266} INFO - Task exited with return code 1
[2025-07-28T01:20:04.960+0000] {local_task_job_runner.py:245} INFO - ::endgroup::
