[2025-07-28T00:18:06.540+0000] {local_task_job_runner.py:123} INFO - ::group::Pre task execution logs
[2025-07-28T00:18:06.614+0000] {taskinstance.py:2614} INFO - Dependencies all met for dep_context=non-requeueable deps ti=<TaskInstance: fraud_detection_training.execute_training scheduled__2025-07-27T00:18:00+00:00 [queued]>
[2025-07-28T00:18:06.642+0000] {taskinstance.py:2614} INFO - Dependencies all met for dep_context=requeueable deps ti=<TaskInstance: fraud_detection_training.execute_training scheduled__2025-07-27T00:18:00+00:00 [queued]>
[2025-07-28T00:18:06.643+0000] {taskinstance.py:2867} INFO - Starting attempt 1 of 1
[2025-07-28T00:18:06.689+0000] {taskinstance.py:2890} INFO - Executing <Task(PythonOperator): execute_training> on 2025-07-27 00:18:00+00:00
[2025-07-28T00:18:06.702+0000] {warnings.py:112} WARNING - /home/***/.local/lib/python3.12/site-packages/***/task/task_runner/standard_task_runner.py:70: DeprecationWarning: This process (pid=1168) is multi-threaded, use of fork() may lead to deadlocks in the child.
  pid = os.fork()

[2025-07-28T00:18:06.704+0000] {standard_task_runner.py:72} INFO - Started process 1169 to run task
[2025-07-28T00:18:06.705+0000] {standard_task_runner.py:104} INFO - Running: ['***', 'tasks', 'run', 'fraud_detection_training', 'execute_training', 'scheduled__2025-07-27T00:18:00+00:00', '--job-id', '83', '--raw', '--subdir', 'DAGS_FOLDER/fraud_detection_training_dag.py', '--cfg-path', '/tmp/tmp8o9tkcn7']
[2025-07-28T00:18:06.708+0000] {standard_task_runner.py:105} INFO - Job 83: Subtask execute_training
[2025-07-28T00:18:06.814+0000] {task_command.py:467} INFO - Running <TaskInstance: fraud_detection_training.execute_training scheduled__2025-07-27T00:18:00+00:00 [running]> on host c0f7bf91f6c3
[2025-07-28T00:18:07.053+0000] {taskinstance.py:3134} INFO - Exporting env vars: AIRFLOW_CTX_DAG_OWNER='kanewyp' AIRFLOW_CTX_DAG_ID='fraud_detection_training' AIRFLOW_CTX_TASK_ID='execute_training' AIRFLOW_CTX_EXECUTION_DATE='2025-07-27T00:18:00+00:00' AIRFLOW_CTX_TRY_NUMBER='1' AIRFLOW_CTX_DAG_RUN_ID='scheduled__2025-07-27T00:18:00+00:00'
[2025-07-28T00:18:07.054+0000] {taskinstance.py:732} INFO - ::endgroup::
[2025-07-28T00:18:17.263+0000] {fraud_detection_training_dag.py:22} INFO - Initializing Fraud Detection Training
[2025-07-28T00:18:17.287+0000] {fraud_detection_training.py:62} INFO - Configuration loaded successfully
[2025-07-28T00:18:18.409+0000] {fraud_detection_training.py:88} INFO - Connected to MinIO. Available buckets: mlflow
[2025-07-28T00:18:19.076+0000] {fraud_detection_training.py:182} INFO - Starting model training process...
[2025-07-28T00:18:19.077+0000] {fraud_detection_training.py:104} INFO - Reading data from Kafka topic: fraud_detection
[2025-07-28T00:18:19.195+0000] {conn.py:396} INFO - <BrokerConnection client_id=kafka-python-2.2.15, node_id=bootstrap-0 host=pkc-ldvj1.ap-southeast-2.aws.confluent.cloud:9092 <connecting> [IPv4 ('52.64.27.176', 9092)]>: connecting to pkc-ldvj1.ap-southeast-2.aws.confluent.cloud:9092 [('52.64.27.176', 9092) IPv4]
[2025-07-28T00:18:19.239+0000] {conn.py:497} INFO - <BrokerConnection client_id=kafka-python-2.2.15, node_id=bootstrap-0 host=pkc-ldvj1.ap-southeast-2.aws.confluent.cloud:9092 <handshake> [IPv4 ('52.64.27.176', 9092)]>: Loading system default SSL CAs from ('/usr/lib/ssl/cert.pem', '/usr/lib/ssl/certs', 'SSL_CERT_FILE', '/usr/lib/ssl/cert.pem', 'SSL_CERT_DIR', '/usr/lib/ssl/certs')
[2025-07-28T00:18:19.472+0000] {conn.py:618} INFO - <BrokerConnection client_id=kafka-python-2.2.15, node_id=bootstrap-0 host=pkc-ldvj1.ap-southeast-2.aws.confluent.cloud:9092 <checking_api_versions_recv> [IPv4 ('52.64.27.176', 9092)]>: Broker version identified as 2.6
[2025-07-28T00:18:19.654+0000] {conn.py:822} INFO - <BrokerConnection client_id=kafka-python-2.2.15, node_id=bootstrap-0 host=pkc-ldvj1.ap-southeast-2.aws.confluent.cloud:9092 <authenticating> [IPv4 ('52.64.27.176', 9092)]>: Authenticated as KQIWVOLDBVJZDLTP via SASL / Plain
[2025-07-28T00:18:19.656+0000] {conn.py:467} INFO - <BrokerConnection client_id=kafka-python-2.2.15, node_id=bootstrap-0 host=pkc-ldvj1.ap-southeast-2.aws.confluent.cloud:9092 <connected> [IPv4 ('52.64.27.176', 9092)]>: Connection complete.
[2025-07-28T00:18:19.657+0000] {consumer.py:120} WARNING - group_id is None: disabling auto-commit.
[2025-07-28T00:18:19.657+0000] {subscription_state.py:181} INFO - Updating subscribed topics to: ('fraud_detection',)
[2025-07-28T00:18:19.697+0000] {subscription_state.py:254} INFO - Updated partition assignment: [('fraud_detection', 0), ('fraud_detection', 1), ('fraud_detection', 2), ('fraud_detection', 3), ('fraud_detection', 4), ('fraud_detection', 5)]
[2025-07-28T00:18:19.828+0000] {conn.py:396} INFO - <BrokerConnection client_id=kafka-python-2.2.15, node_id=0 host=b0-pkc-ldvj1.ap-southeast-2.aws.confluent.cloud:9092 <connecting> [IPv4 ('13.237.213.69', 9092)]>: connecting to b0-pkc-ldvj1.ap-southeast-2.aws.confluent.cloud:9092 [('13.237.213.69', 9092) IPv4]
[2025-07-28T00:18:19.982+0000] {conn.py:396} INFO - <BrokerConnection client_id=kafka-python-2.2.15, node_id=1 host=b1-pkc-ldvj1.ap-southeast-2.aws.confluent.cloud:9092 <connecting> [IPv4 ('3.104.173.57', 9092)]>: connecting to b1-pkc-ldvj1.ap-southeast-2.aws.confluent.cloud:9092 [('3.104.173.57', 9092) IPv4]
[2025-07-28T00:18:20.053+0000] {conn.py:396} INFO - <BrokerConnection client_id=kafka-python-2.2.15, node_id=2 host=b2-pkc-ldvj1.ap-southeast-2.aws.confluent.cloud:9092 <connecting> [IPv4 ('52.63.61.170', 9092)]>: connecting to b2-pkc-ldvj1.ap-southeast-2.aws.confluent.cloud:9092 [('52.63.61.170', 9092) IPv4]
[2025-07-28T00:18:20.131+0000] {conn.py:396} INFO - <BrokerConnection client_id=kafka-python-2.2.15, node_id=3 host=b3-pkc-ldvj1.ap-southeast-2.aws.confluent.cloud:9092 <connecting> [IPv4 ('3.106.149.208', 9092)]>: connecting to b3-pkc-ldvj1.ap-southeast-2.aws.confluent.cloud:9092 [('3.106.149.208', 9092) IPv4]
[2025-07-28T00:18:20.199+0000] {conn.py:396} INFO - <BrokerConnection client_id=kafka-python-2.2.15, node_id=4 host=b4-pkc-ldvj1.ap-southeast-2.aws.confluent.cloud:9092 <connecting> [IPv4 ('13.210.104.107', 9092)]>: connecting to b4-pkc-ldvj1.ap-southeast-2.aws.confluent.cloud:9092 [('13.210.104.107', 9092) IPv4]
[2025-07-28T00:18:20.270+0000] {conn.py:396} INFO - <BrokerConnection client_id=kafka-python-2.2.15, node_id=5 host=b5-pkc-ldvj1.ap-southeast-2.aws.confluent.cloud:9092 <connecting> [IPv4 ('54.252.204.130', 9092)]>: connecting to b5-pkc-ldvj1.ap-southeast-2.aws.confluent.cloud:9092 [('54.252.204.130', 9092) IPv4]
[2025-07-28T00:18:20.273+0000] {conn.py:497} INFO - <BrokerConnection client_id=kafka-python-2.2.15, node_id=0 host=b0-pkc-ldvj1.ap-southeast-2.aws.confluent.cloud:9092 <handshake> [IPv4 ('13.237.213.69', 9092)]>: Loading system default SSL CAs from ('/usr/lib/ssl/cert.pem', '/usr/lib/ssl/certs', 'SSL_CERT_FILE', '/usr/lib/ssl/cert.pem', 'SSL_CERT_DIR', '/usr/lib/ssl/certs')
[2025-07-28T00:18:20.319+0000] {conn.py:497} INFO - <BrokerConnection client_id=kafka-python-2.2.15, node_id=1 host=b1-pkc-ldvj1.ap-southeast-2.aws.confluent.cloud:9092 <handshake> [IPv4 ('3.104.173.57', 9092)]>: Loading system default SSL CAs from ('/usr/lib/ssl/cert.pem', '/usr/lib/ssl/certs', 'SSL_CERT_FILE', '/usr/lib/ssl/cert.pem', 'SSL_CERT_DIR', '/usr/lib/ssl/certs')
[2025-07-28T00:18:20.353+0000] {conn.py:497} INFO - <BrokerConnection client_id=kafka-python-2.2.15, node_id=2 host=b2-pkc-ldvj1.ap-southeast-2.aws.confluent.cloud:9092 <handshake> [IPv4 ('52.63.61.170', 9092)]>: Loading system default SSL CAs from ('/usr/lib/ssl/cert.pem', '/usr/lib/ssl/certs', 'SSL_CERT_FILE', '/usr/lib/ssl/cert.pem', 'SSL_CERT_DIR', '/usr/lib/ssl/certs')
[2025-07-28T00:18:20.385+0000] {conn.py:497} INFO - <BrokerConnection client_id=kafka-python-2.2.15, node_id=3 host=b3-pkc-ldvj1.ap-southeast-2.aws.confluent.cloud:9092 <handshake> [IPv4 ('3.106.149.208', 9092)]>: Loading system default SSL CAs from ('/usr/lib/ssl/cert.pem', '/usr/lib/ssl/certs', 'SSL_CERT_FILE', '/usr/lib/ssl/cert.pem', 'SSL_CERT_DIR', '/usr/lib/ssl/certs')
[2025-07-28T00:18:20.416+0000] {conn.py:497} INFO - <BrokerConnection client_id=kafka-python-2.2.15, node_id=4 host=b4-pkc-ldvj1.ap-southeast-2.aws.confluent.cloud:9092 <handshake> [IPv4 ('13.210.104.107', 9092)]>: Loading system default SSL CAs from ('/usr/lib/ssl/cert.pem', '/usr/lib/ssl/certs', 'SSL_CERT_FILE', '/usr/lib/ssl/cert.pem', 'SSL_CERT_DIR', '/usr/lib/ssl/certs')
[2025-07-28T00:18:20.457+0000] {conn.py:497} INFO - <BrokerConnection client_id=kafka-python-2.2.15, node_id=5 host=b5-pkc-ldvj1.ap-southeast-2.aws.confluent.cloud:9092 <handshake> [IPv4 ('54.252.204.130', 9092)]>: Loading system default SSL CAs from ('/usr/lib/ssl/cert.pem', '/usr/lib/ssl/certs', 'SSL_CERT_FILE', '/usr/lib/ssl/cert.pem', 'SSL_CERT_DIR', '/usr/lib/ssl/certs')
[2025-07-28T00:18:20.662+0000] {conn.py:822} INFO - <BrokerConnection client_id=kafka-python-2.2.15, node_id=0 host=b0-pkc-ldvj1.ap-southeast-2.aws.confluent.cloud:9092 <authenticating> [IPv4 ('13.237.213.69', 9092)]>: Authenticated as KQIWVOLDBVJZDLTP via SASL / Plain
[2025-07-28T00:18:20.663+0000] {conn.py:467} INFO - <BrokerConnection client_id=kafka-python-2.2.15, node_id=0 host=b0-pkc-ldvj1.ap-southeast-2.aws.confluent.cloud:9092 <connected> [IPv4 ('13.237.213.69', 9092)]>: Connection complete.
[2025-07-28T00:18:20.663+0000] {conn.py:945} INFO - <BrokerConnection client_id=kafka-python-2.2.15, node_id=bootstrap-0 host=pkc-ldvj1.ap-southeast-2.aws.confluent.cloud:9092 <connected> [IPv4 ('52.64.27.176', 9092)]>: Closing connection. 
[2025-07-28T00:18:20.802+0000] {conn.py:822} INFO - <BrokerConnection client_id=kafka-python-2.2.15, node_id=2 host=b2-pkc-ldvj1.ap-southeast-2.aws.confluent.cloud:9092 <authenticating> [IPv4 ('52.63.61.170', 9092)]>: Authenticated as KQIWVOLDBVJZDLTP via SASL / Plain
[2025-07-28T00:18:20.804+0000] {conn.py:467} INFO - <BrokerConnection client_id=kafka-python-2.2.15, node_id=2 host=b2-pkc-ldvj1.ap-southeast-2.aws.confluent.cloud:9092 <connected> [IPv4 ('52.63.61.170', 9092)]>: Connection complete.
[2025-07-28T00:18:20.847+0000] {conn.py:822} INFO - <BrokerConnection client_id=kafka-python-2.2.15, node_id=1 host=b1-pkc-ldvj1.ap-southeast-2.aws.confluent.cloud:9092 <authenticating> [IPv4 ('3.104.173.57', 9092)]>: Authenticated as KQIWVOLDBVJZDLTP via SASL / Plain
[2025-07-28T00:18:20.848+0000] {conn.py:467} INFO - <BrokerConnection client_id=kafka-python-2.2.15, node_id=1 host=b1-pkc-ldvj1.ap-southeast-2.aws.confluent.cloud:9092 <connected> [IPv4 ('3.104.173.57', 9092)]>: Connection complete.
[2025-07-28T00:18:20.983+0000] {conn.py:822} INFO - <BrokerConnection client_id=kafka-python-2.2.15, node_id=3 host=b3-pkc-ldvj1.ap-southeast-2.aws.confluent.cloud:9092 <authenticating> [IPv4 ('3.106.149.208', 9092)]>: Authenticated as KQIWVOLDBVJZDLTP via SASL / Plain
[2025-07-28T00:18:20.983+0000] {conn.py:467} INFO - <BrokerConnection client_id=kafka-python-2.2.15, node_id=3 host=b3-pkc-ldvj1.ap-southeast-2.aws.confluent.cloud:9092 <connected> [IPv4 ('3.106.149.208', 9092)]>: Connection complete.
[2025-07-28T00:18:21.112+0000] {conn.py:822} INFO - <BrokerConnection client_id=kafka-python-2.2.15, node_id=4 host=b4-pkc-ldvj1.ap-southeast-2.aws.confluent.cloud:9092 <authenticating> [IPv4 ('13.210.104.107', 9092)]>: Authenticated as KQIWVOLDBVJZDLTP via SASL / Plain
[2025-07-28T00:18:21.113+0000] {conn.py:467} INFO - <BrokerConnection client_id=kafka-python-2.2.15, node_id=4 host=b4-pkc-ldvj1.ap-southeast-2.aws.confluent.cloud:9092 <connected> [IPv4 ('13.210.104.107', 9092)]>: Connection complete.
[2025-07-28T00:18:21.114+0000] {fetcher.py:418} INFO - Resetting offset for partition ('fraud_detection', 0) to offset 0.
[2025-07-28T00:18:21.114+0000] {fetcher.py:418} INFO - Resetting offset for partition ('fraud_detection', 2) to offset 0.
[2025-07-28T00:18:21.250+0000] {conn.py:822} INFO - <BrokerConnection client_id=kafka-python-2.2.15, node_id=5 host=b5-pkc-ldvj1.ap-southeast-2.aws.confluent.cloud:9092 <authenticating> [IPv4 ('54.252.204.130', 9092)]>: Authenticated as KQIWVOLDBVJZDLTP via SASL / Plain
[2025-07-28T00:18:21.251+0000] {conn.py:467} INFO - <BrokerConnection client_id=kafka-python-2.2.15, node_id=5 host=b5-pkc-ldvj1.ap-southeast-2.aws.confluent.cloud:9092 <connected> [IPv4 ('54.252.204.130', 9092)]>: Connection complete.
[2025-07-28T00:18:21.252+0000] {fetcher.py:418} INFO - Resetting offset for partition ('fraud_detection', 1) to offset 0.
[2025-07-28T00:18:21.253+0000] {fetcher.py:418} INFO - Resetting offset for partition ('fraud_detection', 3) to offset 0.
[2025-07-28T00:18:21.253+0000] {fetcher.py:418} INFO - Resetting offset for partition ('fraud_detection', 4) to offset 0.
[2025-07-28T00:18:21.394+0000] {fetcher.py:418} INFO - Resetting offset for partition ('fraud_detection', 5) to offset 0.
[2025-07-28T00:18:51.643+0000] {conn.py:945} INFO - <BrokerConnection client_id=kafka-python-2.2.15, node_id=0 host=b0-pkc-ldvj1.ap-southeast-2.aws.confluent.cloud:9092 <connected> [IPv4 ('13.237.213.69', 9092)]>: Closing connection. 
[2025-07-28T00:18:51.644+0000] {fetcher.py:786} INFO - Fetch to node 0 failed: Cancelled: <BrokerConnection client_id=kafka-python-2.2.15, node_id=0 host=b0-pkc-ldvj1.ap-southeast-2.aws.confluent.cloud:9092 <connected> [IPv4 ('13.237.213.69', 9092)]>
[2025-07-28T00:18:51.645+0000] {conn.py:945} INFO - <BrokerConnection client_id=kafka-python-2.2.15, node_id=1 host=b1-pkc-ldvj1.ap-southeast-2.aws.confluent.cloud:9092 <connected> [IPv4 ('3.104.173.57', 9092)]>: Closing connection. 
[2025-07-28T00:18:51.645+0000] {fetcher.py:786} INFO - Fetch to node 1 failed: Cancelled: <BrokerConnection client_id=kafka-python-2.2.15, node_id=1 host=b1-pkc-ldvj1.ap-southeast-2.aws.confluent.cloud:9092 <connected> [IPv4 ('3.104.173.57', 9092)]>
[2025-07-28T00:18:51.646+0000] {conn.py:945} INFO - <BrokerConnection client_id=kafka-python-2.2.15, node_id=2 host=b2-pkc-ldvj1.ap-southeast-2.aws.confluent.cloud:9092 <connected> [IPv4 ('52.63.61.170', 9092)]>: Closing connection. 
[2025-07-28T00:18:51.646+0000] {fetcher.py:786} INFO - Fetch to node 2 failed: Cancelled: <BrokerConnection client_id=kafka-python-2.2.15, node_id=2 host=b2-pkc-ldvj1.ap-southeast-2.aws.confluent.cloud:9092 <connected> [IPv4 ('52.63.61.170', 9092)]>
[2025-07-28T00:18:51.646+0000] {conn.py:945} INFO - <BrokerConnection client_id=kafka-python-2.2.15, node_id=3 host=b3-pkc-ldvj1.ap-southeast-2.aws.confluent.cloud:9092 <connected> [IPv4 ('3.106.149.208', 9092)]>: Closing connection. 
[2025-07-28T00:18:51.647+0000] {fetcher.py:786} INFO - Fetch to node 3 failed: Cancelled: <BrokerConnection client_id=kafka-python-2.2.15, node_id=3 host=b3-pkc-ldvj1.ap-southeast-2.aws.confluent.cloud:9092 <connected> [IPv4 ('3.106.149.208', 9092)]>
[2025-07-28T00:18:51.647+0000] {conn.py:945} INFO - <BrokerConnection client_id=kafka-python-2.2.15, node_id=4 host=b4-pkc-ldvj1.ap-southeast-2.aws.confluent.cloud:9092 <connected> [IPv4 ('13.210.104.107', 9092)]>: Closing connection. 
[2025-07-28T00:18:51.647+0000] {fetcher.py:786} INFO - Fetch to node 4 failed: Cancelled: <BrokerConnection client_id=kafka-python-2.2.15, node_id=4 host=b4-pkc-ldvj1.ap-southeast-2.aws.confluent.cloud:9092 <connected> [IPv4 ('13.210.104.107', 9092)]>
[2025-07-28T00:18:51.648+0000] {conn.py:945} INFO - <BrokerConnection client_id=kafka-python-2.2.15, node_id=5 host=b5-pkc-ldvj1.ap-southeast-2.aws.confluent.cloud:9092 <connected> [IPv4 ('54.252.204.130', 9092)]>: Closing connection. 
[2025-07-28T00:18:51.648+0000] {fetcher.py:786} INFO - Fetch to node 5 failed: Cancelled: <BrokerConnection client_id=kafka-python-2.2.15, node_id=5 host=b5-pkc-ldvj1.ap-southeast-2.aws.confluent.cloud:9092 <connected> [IPv4 ('54.252.204.130', 9092)]>
[2025-07-28T00:18:52.341+0000] {fraud_detection_training.py:131} INFO - Received 98878 records from Kafka with fraud rate: 0.74%
[2025-07-28T00:19:09.131+0000] {fraud_detection_training.py:263} INFO - Starting hyperparameter tuning...
[2025-07-28T00:30:19.856+0000] {job.py:229} INFO - Heartbeat recovered after 545.45 seconds
[2025-07-28T00:33:53.683+0000] {job.py:229} INFO - Heartbeat recovered after 162.63 seconds
[2025-07-28T00:43:20.774+0000] {local_task_job_runner.py:346} WARNING - State of this instance has been externally set to restarting. Terminating instance.
[2025-07-28T00:43:20.775+0000] {local_task_job_runner.py:245} INFO - ::endgroup::
[2025-07-28T00:43:20.783+0000] {process_utils.py:132} INFO - Sending 15 to group 1169. PIDs of all processes in the group: [1169]
[2025-07-28T00:43:20.783+0000] {process_utils.py:87} INFO - Sending the signal 15 to group 1169
[2025-07-28T00:43:20.804+0000] {taskinstance.py:3094} ERROR - Received SIGTERM. Terminating subprocesses.
[2025-07-28T00:43:20.879+0000] {taskinstance.py:3095} ERROR - Stacktrace: 
  File "/home/***/.local/bin/***", line 8, in <module>
    sys.exit(main())
  File "/home/***/.local/lib/python3.12/site-packages/***/__main__.py", line 62, in main
    args.func(args)
  File "/home/***/.local/lib/python3.12/site-packages/***/cli/cli_config.py", line 49, in command
    return func(*args, **kwargs)
  File "/home/***/.local/lib/python3.12/site-packages/***/utils/cli.py", line 116, in wrapper
    return f(*args, **kwargs)
  File "/home/***/.local/lib/python3.12/site-packages/***/providers/celery/cli/celery_command.py", line 64, in wrapper
    providers_configuration_loaded(func)(*args, **kwargs)
  File "/home/***/.local/lib/python3.12/site-packages/***/utils/providers_configuration_loader.py", line 55, in wrapped_function
    return func(*args, **kwargs)
  File "/home/***/.local/lib/python3.12/site-packages/***/providers/celery/cli/celery_command.py", line 237, in worker
    _run_command_with_daemon_option(
  File "/home/***/.local/lib/python3.12/site-packages/***/providers/celery/cli/celery_command.py", line 50, in _run_command_with_daemon_option
    run_command_with_daemon_option(*args, **kwargs)
  File "/home/***/.local/lib/python3.12/site-packages/***/cli/commands/daemon_utils.py", line 86, in run_command_with_daemon_option
    callback()
  File "/home/***/.local/lib/python3.12/site-packages/***/providers/celery/cli/celery_command.py", line 230, in run_celery_worker
    celery_app.worker_main(options)
  File "/home/***/.local/lib/python3.12/site-packages/celery/app/base.py", line 391, in worker_main
    self.start(argv=argv)
  File "/home/***/.local/lib/python3.12/site-packages/celery/app/base.py", line 371, in start
    celery.main(args=argv, standalone_mode=False)
  File "/home/***/.local/lib/python3.12/site-packages/click/core.py", line 1082, in main
    rv = self.invoke(ctx)
  File "/home/***/.local/lib/python3.12/site-packages/click/core.py", line 1697, in invoke
    return _process_result(sub_ctx.command.invoke(sub_ctx))
  File "/home/***/.local/lib/python3.12/site-packages/click/core.py", line 1443, in invoke
    return ctx.invoke(self.callback, **ctx.params)
  File "/home/***/.local/lib/python3.12/site-packages/click/core.py", line 788, in invoke
    return __callback(*args, **kwargs)
  File "/home/***/.local/lib/python3.12/site-packages/click/decorators.py", line 33, in new_func
    return f(get_current_context(), *args, **kwargs)
  File "/home/***/.local/lib/python3.12/site-packages/celery/bin/base.py", line 135, in caller
    return f(ctx, *args, **kwargs)
  File "/home/***/.local/lib/python3.12/site-packages/celery/bin/worker.py", line 356, in worker
    worker.start()
  File "/home/***/.local/lib/python3.12/site-packages/celery/worker/worker.py", line 202, in start
    self.blueprint.start(self)
  File "/home/***/.local/lib/python3.12/site-packages/celery/bootsteps.py", line 116, in start
    step.start(parent)
  File "/home/***/.local/lib/python3.12/site-packages/celery/bootsteps.py", line 365, in start
    return self.obj.start()
  File "/home/***/.local/lib/python3.12/site-packages/celery/concurrency/base.py", line 130, in start
    self.on_start()
  File "/home/***/.local/lib/python3.12/site-packages/celery/concurrency/prefork.py", line 109, in on_start
    P = self._pool = Pool(processes=self.limit,
  File "/home/***/.local/lib/python3.12/site-packages/celery/concurrency/asynpool.py", line 464, in __init__
    super().__init__(processes, *args, **kwargs)
  File "/home/***/.local/lib/python3.12/site-packages/billiard/pool.py", line 1046, in __init__
    self._create_worker_process(i)
  File "/home/***/.local/lib/python3.12/site-packages/celery/concurrency/asynpool.py", line 482, in _create_worker_process
    return super()._create_worker_process(i)
  File "/home/***/.local/lib/python3.12/site-packages/billiard/pool.py", line 1158, in _create_worker_process
    w.start()
  File "/home/***/.local/lib/python3.12/site-packages/billiard/process.py", line 120, in start
    self._popen = self._Popen(self)
  File "/home/***/.local/lib/python3.12/site-packages/billiard/context.py", line 331, in _Popen
    return Popen(process_obj)
  File "/home/***/.local/lib/python3.12/site-packages/billiard/popen_fork.py", line 22, in __init__
    self._launch(process_obj)
  File "/home/***/.local/lib/python3.12/site-packages/billiard/popen_fork.py", line 77, in _launch
    code = process_obj._bootstrap()
  File "/home/***/.local/lib/python3.12/site-packages/billiard/process.py", line 323, in _bootstrap
    self.run()
  File "/home/***/.local/lib/python3.12/site-packages/billiard/process.py", line 110, in run
    self._target(*self._args, **self._kwargs)
  File "/home/***/.local/lib/python3.12/site-packages/billiard/pool.py", line 292, in __call__
    sys.exit(self.workloop(pid=pid))
  File "/home/***/.local/lib/python3.12/site-packages/billiard/pool.py", line 362, in workloop
    result = (True, prepare_result(fun(*args, **kwargs)))
  File "/home/***/.local/lib/python3.12/site-packages/celery/app/trace.py", line 651, in fast_trace_task
    R, I, T, Rstr = tasks[task].__trace__(
  File "/home/***/.local/lib/python3.12/site-packages/celery/app/trace.py", line 453, in trace_task
    R = retval = fun(*args, **kwargs)
  File "/home/***/.local/lib/python3.12/site-packages/celery/app/trace.py", line 736, in __protected_call__
    return self.run(*args, **kwargs)
  File "/home/***/.local/lib/python3.12/site-packages/***/providers/celery/executors/celery_executor_utils.py", line 139, in execute_command
    _execute_in_fork(command_to_exec, celery_task_id)
  File "/home/***/.local/lib/python3.12/site-packages/***/providers/celery/executors/celery_executor_utils.py", line 171, in _execute_in_fork
    args.func(args)
  File "/home/***/.local/lib/python3.12/site-packages/***/cli/cli_config.py", line 49, in command
    return func(*args, **kwargs)
  File "/home/***/.local/lib/python3.12/site-packages/***/utils/cli.py", line 116, in wrapper
    return f(*args, **kwargs)
  File "/home/***/.local/lib/python3.12/site-packages/***/cli/commands/task_command.py", line 483, in task_run
    task_return_code = _run_task_by_selected_method(args, _dag, ti)
  File "/home/***/.local/lib/python3.12/site-packages/***/cli/commands/task_command.py", line 254, in _run_task_by_selected_method
    return _run_task_by_local_task_job(args, ti)
  File "/home/***/.local/lib/python3.12/site-packages/***/cli/commands/task_command.py", line 322, in _run_task_by_local_task_job
    ret = run_job(job=job_runner.job, execute_callable=job_runner._execute)
  File "/home/***/.local/lib/python3.12/site-packages/***/utils/session.py", line 97, in wrapper
    return func(*args, session=session, **kwargs)
  File "/home/***/.local/lib/python3.12/site-packages/***/jobs/job.py", line 421, in run_job
    return execute_job(job, execute_callable=execute_callable)
  File "/home/***/.local/lib/python3.12/site-packages/***/jobs/job.py", line 450, in execute_job
    ret = execute_callable()
  File "/home/***/.local/lib/python3.12/site-packages/***/jobs/local_task_job_runner.py", line 171, in _execute
    self.task_runner.start()
  File "/home/***/.local/lib/python3.12/site-packages/***/task/task_runner/standard_task_runner.py", line 55, in start
    self.process = self._start_by_fork()
  File "/home/***/.local/lib/python3.12/site-packages/***/task/task_runner/standard_task_runner.py", line 117, in _start_by_fork
    ret = args.func(args, dag=self.dag)
  File "/home/***/.local/lib/python3.12/site-packages/***/cli/cli_config.py", line 49, in command
    return func(*args, **kwargs)
  File "/home/***/.local/lib/python3.12/site-packages/***/utils/cli.py", line 116, in wrapper
    return f(*args, **kwargs)
  File "/home/***/.local/lib/python3.12/site-packages/***/cli/commands/task_command.py", line 483, in task_run
    task_return_code = _run_task_by_selected_method(args, _dag, ti)
  File "/home/***/.local/lib/python3.12/site-packages/***/cli/commands/task_command.py", line 256, in _run_task_by_selected_method
    return _run_raw_task(args, ti)
  File "/home/***/.local/lib/python3.12/site-packages/***/cli/commands/task_command.py", line 341, in _run_raw_task
    return ti._run_raw_task(
  File "/home/***/.local/lib/python3.12/site-packages/***/utils/session.py", line 97, in wrapper
    return func(*args, session=session, **kwargs)
  File "/home/***/.local/lib/python3.12/site-packages/***/models/taskinstance.py", line 3006, in _run_raw_task
    return _run_raw_task(
  File "/home/***/.local/lib/python3.12/site-packages/***/models/taskinstance.py", line 274, in _run_raw_task
    TaskInstance._execute_task_with_callbacks(
  File "/home/***/.local/lib/python3.12/site-packages/***/models/taskinstance.py", line 3161, in _execute_task_with_callbacks
    result = self._execute_task(context, task_orig)
  File "/home/***/.local/lib/python3.12/site-packages/***/models/taskinstance.py", line 3185, in _execute_task
    return _execute_task(self, context, task_orig)
  File "/home/***/.local/lib/python3.12/site-packages/***/models/taskinstance.py", line 768, in _execute_task
    result = _execute_callable(context=context, **execute_callable_kwargs)
  File "/home/***/.local/lib/python3.12/site-packages/***/models/taskinstance.py", line 734, in _execute_callable
    return ExecutionCallableRunner(
  File "/home/***/.local/lib/python3.12/site-packages/***/utils/operator_helpers.py", line 252, in run
    return self.func(*args, **kwargs)
  File "/home/***/.local/lib/python3.12/site-packages/***/models/baseoperator.py", line 424, in wrapper
    return func(self, *args, **kwargs)
  File "/home/***/.local/lib/python3.12/site-packages/***/operators/python.py", line 238, in execute
    return_value = self.execute_callable()
  File "/home/***/.local/lib/python3.12/site-packages/***/operators/python.py", line 256, in execute_callable
    return runner.run(*self.op_args, **self.op_kwargs)
  File "/home/***/.local/lib/python3.12/site-packages/***/utils/operator_helpers.py", line 252, in run
    return self.func(*args, **kwargs)
  File "/opt/***/dags/fraud_detection_training_dag.py", line 24, in _train_model
    model, precision = trainer.train_model()
  File "/opt/***/dags/fraud_detection_training.py", line 264, in train_model
    searcher.fit(X_train, y_train)
  File "/home/***/.local/lib/python3.12/site-packages/sklearn/base.py", line 1389, in wrapper
    return fit_method(estimator, *args, **kwargs)
  File "/home/***/.local/lib/python3.12/site-packages/sklearn/model_selection/_search.py", line 1024, in fit
    self._run_search(evaluate_candidates)
  File "/home/***/.local/lib/python3.12/site-packages/sklearn/model_selection/_search.py", line 1951, in _run_search
    evaluate_candidates(
  File "/home/***/.local/lib/python3.12/site-packages/sklearn/model_selection/_search.py", line 970, in evaluate_candidates
    out = parallel(
  File "/home/***/.local/lib/python3.12/site-packages/sklearn/utils/parallel.py", line 77, in __call__
    return super().__call__(iterable_with_config)
  File "/home/***/.local/lib/python3.12/site-packages/joblib/parallel.py", line 1986, in __call__
    return output if self.return_generator else list(output)
  File "/home/***/.local/lib/python3.12/site-packages/joblib/parallel.py", line 1914, in _get_sequential_output
    res = func(*args, **kwargs)
  File "/home/***/.local/lib/python3.12/site-packages/sklearn/utils/parallel.py", line 139, in __call__
    return self.function(*args, **kwargs)
  File "/home/***/.local/lib/python3.12/site-packages/sklearn/model_selection/_validation.py", line 866, in _fit_and_score
    estimator.fit(X_train, y_train, **fit_params)
  File "/home/***/.local/lib/python3.12/site-packages/sklearn/base.py", line 1389, in wrapper
    return fit_method(estimator, *args, **kwargs)
  File "/home/***/.local/lib/python3.12/site-packages/imblearn/pipeline.py", line 526, in fit
    self._final_estimator.fit(Xt, yt, **last_step_params["fit"])
  File "/home/***/.local/lib/python3.12/site-packages/xgboost/core.py", line 729, in inner_f
    return func(**kwargs)
  File "/home/***/.local/lib/python3.12/site-packages/xgboost/sklearn.py", line 1682, in fit
    self._Booster = train(
  File "/home/***/.local/lib/python3.12/site-packages/xgboost/core.py", line 729, in inner_f
    return func(**kwargs)
  File "/home/***/.local/lib/python3.12/site-packages/xgboost/training.py", line 183, in train
    bst.update(dtrain, iteration=i, fobj=obj)
  File "/home/***/.local/lib/python3.12/site-packages/xgboost/core.py", line 2247, in update
    _LIB.XGBoosterUpdateOneIter(
  File "/home/***/.local/lib/python3.12/site-packages/***/models/taskinstance.py", line 3095, in signal_handler
    self.log.error("Stacktrace: \n%s", "".join(traceback.format_stack()))

[2025-07-28T00:43:20.924+0000] {logging_mixin.py:190} INFO - 🏃 View run chill-midge-89 at: http://mlflow-server:5500/#/experiments/1/runs/b823a96d191240d78975cfa35b46ec2e
[2025-07-28T00:43:20.925+0000] {logging_mixin.py:190} INFO - 🧪 View experiment at: http://mlflow-server:5500/#/experiments/1
[2025-07-28T00:43:20.988+0000] {taskinstance.py:3313} ERROR - Task failed with exception
Traceback (most recent call last):
  File "/home/airflow/.local/lib/python3.12/site-packages/airflow/models/taskinstance.py", line 768, in _execute_task
    result = _execute_callable(context=context, **execute_callable_kwargs)
             ^^^^^^^^^^^^^^^^^^^^^^^^^^^^^^^^^^^^^^^^^^^^^^^^^^^^^^^^^^^^^
  File "/home/airflow/.local/lib/python3.12/site-packages/airflow/models/taskinstance.py", line 734, in _execute_callable
    return ExecutionCallableRunner(
           ^^^^^^^^^^^^^^^^^^^^^^^^
  File "/home/airflow/.local/lib/python3.12/site-packages/airflow/utils/operator_helpers.py", line 252, in run
    return self.func(*args, **kwargs)
           ^^^^^^^^^^^^^^^^^^^^^^^^^^
  File "/home/airflow/.local/lib/python3.12/site-packages/airflow/models/baseoperator.py", line 424, in wrapper
    return func(self, *args, **kwargs)
           ^^^^^^^^^^^^^^^^^^^^^^^^^^^
  File "/home/airflow/.local/lib/python3.12/site-packages/airflow/operators/python.py", line 238, in execute
    return_value = self.execute_callable()
                   ^^^^^^^^^^^^^^^^^^^^^^^
  File "/home/airflow/.local/lib/python3.12/site-packages/airflow/operators/python.py", line 256, in execute_callable
    return runner.run(*self.op_args, **self.op_kwargs)
           ^^^^^^^^^^^^^^^^^^^^^^^^^^^^^^^^^^^^^^^^^^^
  File "/home/airflow/.local/lib/python3.12/site-packages/airflow/utils/operator_helpers.py", line 252, in run
    return self.func(*args, **kwargs)
           ^^^^^^^^^^^^^^^^^^^^^^^^^^
  File "/opt/airflow/dags/fraud_detection_training_dag.py", line 24, in _train_model
    model, precision = trainer.train_model()
                       ^^^^^^^^^^^^^^^^^^^^^
  File "/opt/airflow/dags/fraud_detection_training.py", line 264, in train_model
    searcher.fit(X_train, y_train)
  File "/home/airflow/.local/lib/python3.12/site-packages/sklearn/base.py", line 1389, in wrapper
    return fit_method(estimator, *args, **kwargs)
           ^^^^^^^^^^^^^^^^^^^^^^^^^^^^^^^^^^^^^^
  File "/home/airflow/.local/lib/python3.12/site-packages/sklearn/model_selection/_search.py", line 1024, in fit
    self._run_search(evaluate_candidates)
  File "/home/airflow/.local/lib/python3.12/site-packages/sklearn/model_selection/_search.py", line 1951, in _run_search
    evaluate_candidates(
  File "/home/airflow/.local/lib/python3.12/site-packages/sklearn/model_selection/_search.py", line 970, in evaluate_candidates
    out = parallel(
          ^^^^^^^^^
  File "/home/airflow/.local/lib/python3.12/site-packages/sklearn/utils/parallel.py", line 77, in __call__
    return super().__call__(iterable_with_config)
           ^^^^^^^^^^^^^^^^^^^^^^^^^^^^^^^^^^^^^^
  File "/home/airflow/.local/lib/python3.12/site-packages/joblib/parallel.py", line 1986, in __call__
    return output if self.return_generator else list(output)
                                                ^^^^^^^^^^^^
  File "/home/airflow/.local/lib/python3.12/site-packages/joblib/parallel.py", line 1914, in _get_sequential_output
    res = func(*args, **kwargs)
          ^^^^^^^^^^^^^^^^^^^^^
  File "/home/airflow/.local/lib/python3.12/site-packages/sklearn/utils/parallel.py", line 139, in __call__
    return self.function(*args, **kwargs)
           ^^^^^^^^^^^^^^^^^^^^^^^^^^^^^^
  File "/home/airflow/.local/lib/python3.12/site-packages/sklearn/model_selection/_validation.py", line 866, in _fit_and_score
    estimator.fit(X_train, y_train, **fit_params)
  File "/home/airflow/.local/lib/python3.12/site-packages/sklearn/base.py", line 1389, in wrapper
    return fit_method(estimator, *args, **kwargs)
           ^^^^^^^^^^^^^^^^^^^^^^^^^^^^^^^^^^^^^^
  File "/home/airflow/.local/lib/python3.12/site-packages/imblearn/pipeline.py", line 526, in fit
    self._final_estimator.fit(Xt, yt, **last_step_params["fit"])
  File "/home/airflow/.local/lib/python3.12/site-packages/xgboost/core.py", line 729, in inner_f
    return func(**kwargs)
           ^^^^^^^^^^^^^^
  File "/home/airflow/.local/lib/python3.12/site-packages/xgboost/sklearn.py", line 1682, in fit
    self._Booster = train(
                    ^^^^^^
  File "/home/airflow/.local/lib/python3.12/site-packages/xgboost/core.py", line 729, in inner_f
    return func(**kwargs)
           ^^^^^^^^^^^^^^
  File "/home/airflow/.local/lib/python3.12/site-packages/xgboost/training.py", line 183, in train
    bst.update(dtrain, iteration=i, fobj=obj)
  File "/home/airflow/.local/lib/python3.12/site-packages/xgboost/core.py", line 2247, in update
    _LIB.XGBoosterUpdateOneIter(
  File "/home/airflow/.local/lib/python3.12/site-packages/airflow/models/taskinstance.py", line 3097, in signal_handler
    raise AirflowTaskTerminated("Task received SIGTERM signal")
airflow.exceptions.AirflowTaskTerminated: Task received SIGTERM signal
[2025-07-28T00:43:20.992+0000] {taskinstance.py:1226} INFO - Marking task as UP_FOR_RETRY. dag_id=fraud_detection_training, task_id=execute_training, run_id=scheduled__2025-07-27T00:18:00+00:00, execution_date=20250727T001800, start_date=20250728T001806, end_date=20250728T004320
[2025-07-28T00:43:21.046+0000] {taskinstance.py:341} INFO - ::group::Post task execution logs
[2025-07-28T00:43:21.161+0000] {process_utils.py:80} INFO - Process psutil.Process(pid=1169, status='terminated', exitcode=2, started='00:18:06') (1169) terminated with exit code 2
[2025-07-28T12:26:44.572+0000] {local_task_job_runner.py:123} INFO - ::group::Pre task execution logs
[2025-07-28T12:26:44.589+0000] {taskinstance.py:2614} INFO - Dependencies all met for dep_context=non-requeueable deps ti=<TaskInstance: fraud_detection_training.execute_training scheduled__2025-07-27T00:18:00+00:00 [queued]>
[2025-07-28T12:26:44.595+0000] {taskinstance.py:2614} INFO - Dependencies all met for dep_context=requeueable deps ti=<TaskInstance: fraud_detection_training.execute_training scheduled__2025-07-27T00:18:00+00:00 [queued]>
[2025-07-28T12:26:44.595+0000] {taskinstance.py:2867} INFO - Starting attempt 1 of 1
[2025-07-28T12:26:44.604+0000] {taskinstance.py:2890} INFO - Executing <Task(PythonOperator): execute_training> on 2025-07-27 00:18:00+00:00
[2025-07-28T12:26:44.609+0000] {warnings.py:112} WARNING - /home/***/.local/lib/python3.12/site-packages/***/task/task_runner/standard_task_runner.py:70: DeprecationWarning: This process (pid=90) is multi-threaded, use of fork() may lead to deadlocks in the child.
  pid = os.fork()

[2025-07-28T12:26:44.610+0000] {standard_task_runner.py:72} INFO - Started process 91 to run task
[2025-07-28T12:26:44.610+0000] {standard_task_runner.py:104} INFO - Running: ['***', 'tasks', 'run', 'fraud_detection_training', 'execute_training', 'scheduled__2025-07-27T00:18:00+00:00', '--job-id', '4', '--raw', '--subdir', 'DAGS_FOLDER/fraud_detection_training_dag.py', '--cfg-path', '/tmp/tmpf1kh3nax']
[2025-07-28T12:26:44.611+0000] {standard_task_runner.py:105} INFO - Job 4: Subtask execute_training
[2025-07-28T12:26:44.650+0000] {task_command.py:467} INFO - Running <TaskInstance: fraud_detection_training.execute_training scheduled__2025-07-27T00:18:00+00:00 [running]> on host 28f4427a9e0a
[2025-07-28T12:26:44.712+0000] {taskinstance.py:3134} INFO - Exporting env vars: AIRFLOW_CTX_DAG_OWNER='kanewyp' AIRFLOW_CTX_DAG_ID='fraud_detection_training' AIRFLOW_CTX_TASK_ID='execute_training' AIRFLOW_CTX_EXECUTION_DATE='2025-07-27T00:18:00+00:00' AIRFLOW_CTX_TRY_NUMBER='1' AIRFLOW_CTX_DAG_RUN_ID='scheduled__2025-07-27T00:18:00+00:00'
[2025-07-28T12:26:44.713+0000] {taskinstance.py:732} INFO - ::endgroup::
[2025-07-28T12:26:48.616+0000] {font_manager.py:1639} INFO - generated new fontManager
[2025-07-28T12:26:48.783+0000] {fraud_detection_training_dag.py:22} INFO - Initializing Fraud Detection Training
[2025-07-28T12:26:48.790+0000] {fraud_detection_training.py:62} INFO - Configuration loaded successfully
[2025-07-28T12:26:49.132+0000] {fraud_detection_training.py:88} INFO - Connected to MinIO. Available buckets: mlflow
[2025-07-28T12:26:49.403+0000] {connectionpool.py:868} WARNING - Retrying (Retry(total=6, connect=6, read=7, redirect=7, status=7)) after connection broken by 'NewConnectionError('<urllib3.connection.HTTPConnection object at 0x7be52f1ee8a0>: Failed to establish a new connection: [Errno 111] Connection refused')': /api/2.0/mlflow/experiments/get-by-name?experiment_name=fraud_detection
[2025-07-28T12:26:54.136+0000] {connectionpool.py:868} WARNING - Retrying (Retry(total=5, connect=5, read=7, redirect=7, status=7)) after connection broken by 'NewConnectionError('<urllib3.connection.HTTPConnection object at 0x7be52effd9d0>: Failed to establish a new connection: [Errno 111] Connection refused')': /api/2.0/mlflow/experiments/get-by-name?experiment_name=fraud_detection
[2025-07-28T12:27:03.574+0000] {connectionpool.py:868} WARNING - Retrying (Retry(total=4, connect=4, read=7, redirect=7, status=7)) after connection broken by 'NewConnectionError('<urllib3.connection.HTTPConnection object at 0x7be52e77e510>: Failed to establish a new connection: [Errno 111] Connection refused')': /api/2.0/mlflow/experiments/get-by-name?experiment_name=fraud_detection
[2025-07-28T12:27:19.617+0000] {connectionpool.py:868} WARNING - Retrying (Retry(total=3, connect=3, read=7, redirect=7, status=7)) after connection broken by 'NewConnectionError('<urllib3.connection.HTTPConnection object at 0x7be52e77c5c0>: Failed to establish a new connection: [Errno 111] Connection refused')': /api/2.0/mlflow/experiments/get-by-name?experiment_name=fraud_detection
[2025-07-28T12:27:52.954+0000] {connectionpool.py:868} WARNING - Retrying (Retry(total=2, connect=2, read=7, redirect=7, status=7)) after connection broken by 'NewConnectionError('<urllib3.connection.HTTPConnection object at 0x7be52e77d640>: Failed to establish a new connection: [Errno 111] Connection refused')': /api/2.0/mlflow/experiments/get-by-name?experiment_name=fraud_detection
[2025-07-28T12:28:58.995+0000] {connectionpool.py:868} WARNING - Retrying (Retry(total=1, connect=1, read=7, redirect=7, status=7)) after connection broken by 'NewConnectionError('<urllib3.connection.HTTPConnection object at 0x7be52e77d3a0>: Failed to establish a new connection: [Errno 111] Connection refused')': /api/2.0/mlflow/experiments/get-by-name?experiment_name=fraud_detection
[2025-07-28T12:31:02.944+0000] {connectionpool.py:868} WARNING - Retrying (Retry(total=0, connect=0, read=7, redirect=7, status=7)) after connection broken by 'NewConnectionError('<urllib3.connection.HTTPConnection object at 0x7be52e77c830>: Failed to establish a new connection: [Errno 111] Connection refused')': /api/2.0/mlflow/experiments/get-by-name?experiment_name=fraud_detection
[2025-07-28T12:31:02.950+0000] {fraud_detection_training_dag.py:28} ERROR - Training failed: API request to http://mlflow-server:5500/api/2.0/mlflow/experiments/get-by-name failed with exception HTTPConnectionPool(host='mlflow-server', port=5500): Max retries exceeded with url: /api/2.0/mlflow/experiments/get-by-name?experiment_name=fraud_detection (Caused by NewConnectionError('<urllib3.connection.HTTPConnection object at 0x7be52e77cc20>: Failed to establish a new connection: [Errno 111] Connection refused'))
Traceback (most recent call last):
  File "/home/airflow/.local/lib/python3.12/site-packages/urllib3/connection.py", line 198, in _new_conn
    sock = connection.create_connection(
           ^^^^^^^^^^^^^^^^^^^^^^^^^^^^^
  File "/home/airflow/.local/lib/python3.12/site-packages/urllib3/util/connection.py", line 85, in create_connection
    raise err
  File "/home/airflow/.local/lib/python3.12/site-packages/urllib3/util/connection.py", line 73, in create_connection
    sock.connect(sa)
ConnectionRefusedError: [Errno 111] Connection refused

The above exception was the direct cause of the following exception:

Traceback (most recent call last):
  File "/home/airflow/.local/lib/python3.12/site-packages/urllib3/connectionpool.py", line 787, in urlopen
    response = self._make_request(
               ^^^^^^^^^^^^^^^^^^^
  File "/home/airflow/.local/lib/python3.12/site-packages/urllib3/connectionpool.py", line 493, in _make_request
    conn.request(
  File "/home/airflow/.local/lib/python3.12/site-packages/urllib3/connection.py", line 445, in request
    self.endheaders()
  File "/usr/local/lib/python3.12/http/client.py", line 1333, in endheaders
    self._send_output(message_body, encode_chunked=encode_chunked)
  File "/usr/local/lib/python3.12/http/client.py", line 1093, in _send_output
    self.send(msg)
  File "/usr/local/lib/python3.12/http/client.py", line 1037, in send
    self.connect()
  File "/home/airflow/.local/lib/python3.12/site-packages/urllib3/connection.py", line 276, in connect
    self.sock = self._new_conn()
                ^^^^^^^^^^^^^^^^
  File "/home/airflow/.local/lib/python3.12/site-packages/urllib3/connection.py", line 213, in _new_conn
    raise NewConnectionError(
urllib3.exceptions.NewConnectionError: <urllib3.connection.HTTPConnection object at 0x7be52e77cc20>: Failed to establish a new connection: [Errno 111] Connection refused

The above exception was the direct cause of the following exception:

Traceback (most recent call last):
  File "/home/airflow/.local/lib/python3.12/site-packages/requests/adapters.py", line 667, in send
    resp = conn.urlopen(
           ^^^^^^^^^^^^^
  File "/home/airflow/.local/lib/python3.12/site-packages/urllib3/connectionpool.py", line 871, in urlopen
    return self.urlopen(
           ^^^^^^^^^^^^^
  File "/home/airflow/.local/lib/python3.12/site-packages/urllib3/connectionpool.py", line 871, in urlopen
    return self.urlopen(
           ^^^^^^^^^^^^^
  File "/home/airflow/.local/lib/python3.12/site-packages/urllib3/connectionpool.py", line 871, in urlopen
    return self.urlopen(
           ^^^^^^^^^^^^^
  [Previous line repeated 4 more times]
  File "/home/airflow/.local/lib/python3.12/site-packages/urllib3/connectionpool.py", line 841, in urlopen
    retries = retries.increment(
              ^^^^^^^^^^^^^^^^^^
  File "/home/airflow/.local/lib/python3.12/site-packages/urllib3/util/retry.py", line 519, in increment
    raise MaxRetryError(_pool, url, reason) from reason  # type: ignore[arg-type]
    ^^^^^^^^^^^^^^^^^^^^^^^^^^^^^^^^^^^^^^^^^^^^^^^^^^^
urllib3.exceptions.MaxRetryError: HTTPConnectionPool(host='mlflow-server', port=5500): Max retries exceeded with url: /api/2.0/mlflow/experiments/get-by-name?experiment_name=fraud_detection (Caused by NewConnectionError('<urllib3.connection.HTTPConnection object at 0x7be52e77cc20>: Failed to establish a new connection: [Errno 111] Connection refused'))

During handling of the above exception, another exception occurred:

Traceback (most recent call last):
  File "/home/airflow/.local/lib/python3.12/site-packages/mlflow/utils/rest_utils.py", line 230, in http_request
    return _get_http_response_with_retries(
           ^^^^^^^^^^^^^^^^^^^^^^^^^^^^^^^^
  File "/home/airflow/.local/lib/python3.12/site-packages/mlflow/utils/request_utils.py", line 237, in _get_http_response_with_retries
    return session.request(method, url, allow_redirects=allow_redirects, **kwargs)
           ^^^^^^^^^^^^^^^^^^^^^^^^^^^^^^^^^^^^^^^^^^^^^^^^^^^^^^^^^^^^^^^^^^^^^^^
  File "/home/airflow/.local/lib/python3.12/site-packages/requests/sessions.py", line 589, in request
    resp = self.send(prep, **send_kwargs)
           ^^^^^^^^^^^^^^^^^^^^^^^^^^^^^^
  File "/home/airflow/.local/lib/python3.12/site-packages/requests/sessions.py", line 703, in send
    r = adapter.send(request, **kwargs)
        ^^^^^^^^^^^^^^^^^^^^^^^^^^^^^^^
  File "/home/airflow/.local/lib/python3.12/site-packages/requests/adapters.py", line 700, in send
    raise ConnectionError(e, request=request)
requests.exceptions.ConnectionError: HTTPConnectionPool(host='mlflow-server', port=5500): Max retries exceeded with url: /api/2.0/mlflow/experiments/get-by-name?experiment_name=fraud_detection (Caused by NewConnectionError('<urllib3.connection.HTTPConnection object at 0x7be52e77cc20>: Failed to establish a new connection: [Errno 111] Connection refused'))

During handling of the above exception, another exception occurred:

Traceback (most recent call last):
  File "/opt/airflow/dags/fraud_detection_training_dag.py", line 23, in _train_model
    trainer = FraudDetectionTraining()
              ^^^^^^^^^^^^^^^^^^^^^^^^
  File "/opt/airflow/dags/fraud_detection_training.py", line 55, in __init__
    mlflow.set_experiment(self.config['mlflow']['experiment_name'])
  File "/home/airflow/.local/lib/python3.12/site-packages/mlflow/tracking/fluent.py", line 183, in set_experiment
    experiment = client.get_experiment_by_name(experiment_name)
                 ^^^^^^^^^^^^^^^^^^^^^^^^^^^^^^^^^^^^^^^^^^^^^^
  File "/home/airflow/.local/lib/python3.12/site-packages/mlflow/tracking/_tracking_service/client.py", line 258, in get_experiment_by_name
    return self.store.get_experiment_by_name(name)
           ^^^^^^^^^^^^^^^^^^^^^^^^^^^^^^^^^^^^^^^
  File "/home/airflow/.local/lib/python3.12/site-packages/mlflow/store/tracking/rest_store.py", line 869, in get_experiment_by_name
    response_proto = self._call_endpoint(GetExperimentByName, req_body)
                     ^^^^^^^^^^^^^^^^^^^^^^^^^^^^^^^^^^^^^^^^^^^^^^^^^^
  File "/home/airflow/.local/lib/python3.12/site-packages/mlflow/store/tracking/rest_store.py", line 135, in _call_endpoint
    return call_endpoint(
           ^^^^^^^^^^^^^^
  File "/home/airflow/.local/lib/python3.12/site-packages/mlflow/utils/rest_utils.py", line 589, in call_endpoint
    response = http_request(**call_kwargs)
               ^^^^^^^^^^^^^^^^^^^^^^^^^^^
  File "/home/airflow/.local/lib/python3.12/site-packages/mlflow/utils/rest_utils.py", line 253, in http_request
    raise MlflowException(f"API request to {url} failed with exception {e}")
mlflow.exceptions.MlflowException: API request to http://mlflow-server:5500/api/2.0/mlflow/experiments/get-by-name failed with exception HTTPConnectionPool(host='mlflow-server', port=5500): Max retries exceeded with url: /api/2.0/mlflow/experiments/get-by-name?experiment_name=fraud_detection (Caused by NewConnectionError('<urllib3.connection.HTTPConnection object at 0x7be52e77cc20>: Failed to establish a new connection: [Errno 111] Connection refused'))
[2025-07-28T12:31:02.972+0000] {taskinstance.py:3313} ERROR - Task failed with exception
Traceback (most recent call last):
  File "/home/airflow/.local/lib/python3.12/site-packages/urllib3/connection.py", line 198, in _new_conn
    sock = connection.create_connection(
           ^^^^^^^^^^^^^^^^^^^^^^^^^^^^^
  File "/home/airflow/.local/lib/python3.12/site-packages/urllib3/util/connection.py", line 85, in create_connection
    raise err
  File "/home/airflow/.local/lib/python3.12/site-packages/urllib3/util/connection.py", line 73, in create_connection
    sock.connect(sa)
ConnectionRefusedError: [Errno 111] Connection refused

The above exception was the direct cause of the following exception:

Traceback (most recent call last):
  File "/home/airflow/.local/lib/python3.12/site-packages/urllib3/connectionpool.py", line 787, in urlopen
    response = self._make_request(
               ^^^^^^^^^^^^^^^^^^^
  File "/home/airflow/.local/lib/python3.12/site-packages/urllib3/connectionpool.py", line 493, in _make_request
    conn.request(
  File "/home/airflow/.local/lib/python3.12/site-packages/urllib3/connection.py", line 445, in request
    self.endheaders()
  File "/usr/local/lib/python3.12/http/client.py", line 1333, in endheaders
    self._send_output(message_body, encode_chunked=encode_chunked)
  File "/usr/local/lib/python3.12/http/client.py", line 1093, in _send_output
    self.send(msg)
  File "/usr/local/lib/python3.12/http/client.py", line 1037, in send
    self.connect()
  File "/home/airflow/.local/lib/python3.12/site-packages/urllib3/connection.py", line 276, in connect
    self.sock = self._new_conn()
                ^^^^^^^^^^^^^^^^
  File "/home/airflow/.local/lib/python3.12/site-packages/urllib3/connection.py", line 213, in _new_conn
    raise NewConnectionError(
urllib3.exceptions.NewConnectionError: <urllib3.connection.HTTPConnection object at 0x7be52e77cc20>: Failed to establish a new connection: [Errno 111] Connection refused

The above exception was the direct cause of the following exception:

Traceback (most recent call last):
  File "/home/airflow/.local/lib/python3.12/site-packages/requests/adapters.py", line 667, in send
    resp = conn.urlopen(
           ^^^^^^^^^^^^^
  File "/home/airflow/.local/lib/python3.12/site-packages/urllib3/connectionpool.py", line 871, in urlopen
    return self.urlopen(
           ^^^^^^^^^^^^^
  File "/home/airflow/.local/lib/python3.12/site-packages/urllib3/connectionpool.py", line 871, in urlopen
    return self.urlopen(
           ^^^^^^^^^^^^^
  File "/home/airflow/.local/lib/python3.12/site-packages/urllib3/connectionpool.py", line 871, in urlopen
    return self.urlopen(
           ^^^^^^^^^^^^^
  [Previous line repeated 4 more times]
  File "/home/airflow/.local/lib/python3.12/site-packages/urllib3/connectionpool.py", line 841, in urlopen
    retries = retries.increment(
              ^^^^^^^^^^^^^^^^^^
  File "/home/airflow/.local/lib/python3.12/site-packages/urllib3/util/retry.py", line 519, in increment
    raise MaxRetryError(_pool, url, reason) from reason  # type: ignore[arg-type]
    ^^^^^^^^^^^^^^^^^^^^^^^^^^^^^^^^^^^^^^^^^^^^^^^^^^^
urllib3.exceptions.MaxRetryError: HTTPConnectionPool(host='mlflow-server', port=5500): Max retries exceeded with url: /api/2.0/mlflow/experiments/get-by-name?experiment_name=fraud_detection (Caused by NewConnectionError('<urllib3.connection.HTTPConnection object at 0x7be52e77cc20>: Failed to establish a new connection: [Errno 111] Connection refused'))

During handling of the above exception, another exception occurred:

Traceback (most recent call last):
  File "/home/airflow/.local/lib/python3.12/site-packages/mlflow/utils/rest_utils.py", line 230, in http_request
    return _get_http_response_with_retries(
           ^^^^^^^^^^^^^^^^^^^^^^^^^^^^^^^^
  File "/home/airflow/.local/lib/python3.12/site-packages/mlflow/utils/request_utils.py", line 237, in _get_http_response_with_retries
    return session.request(method, url, allow_redirects=allow_redirects, **kwargs)
           ^^^^^^^^^^^^^^^^^^^^^^^^^^^^^^^^^^^^^^^^^^^^^^^^^^^^^^^^^^^^^^^^^^^^^^^
  File "/home/airflow/.local/lib/python3.12/site-packages/requests/sessions.py", line 589, in request
    resp = self.send(prep, **send_kwargs)
           ^^^^^^^^^^^^^^^^^^^^^^^^^^^^^^
  File "/home/airflow/.local/lib/python3.12/site-packages/requests/sessions.py", line 703, in send
    r = adapter.send(request, **kwargs)
        ^^^^^^^^^^^^^^^^^^^^^^^^^^^^^^^
  File "/home/airflow/.local/lib/python3.12/site-packages/requests/adapters.py", line 700, in send
    raise ConnectionError(e, request=request)
requests.exceptions.ConnectionError: HTTPConnectionPool(host='mlflow-server', port=5500): Max retries exceeded with url: /api/2.0/mlflow/experiments/get-by-name?experiment_name=fraud_detection (Caused by NewConnectionError('<urllib3.connection.HTTPConnection object at 0x7be52e77cc20>: Failed to establish a new connection: [Errno 111] Connection refused'))

During handling of the above exception, another exception occurred:

Traceback (most recent call last):
  File "/opt/airflow/dags/fraud_detection_training_dag.py", line 23, in _train_model
    trainer = FraudDetectionTraining()
              ^^^^^^^^^^^^^^^^^^^^^^^^
  File "/opt/airflow/dags/fraud_detection_training.py", line 55, in __init__
    mlflow.set_experiment(self.config['mlflow']['experiment_name'])
  File "/home/airflow/.local/lib/python3.12/site-packages/mlflow/tracking/fluent.py", line 183, in set_experiment
    experiment = client.get_experiment_by_name(experiment_name)
                 ^^^^^^^^^^^^^^^^^^^^^^^^^^^^^^^^^^^^^^^^^^^^^^
  File "/home/airflow/.local/lib/python3.12/site-packages/mlflow/tracking/_tracking_service/client.py", line 258, in get_experiment_by_name
    return self.store.get_experiment_by_name(name)
           ^^^^^^^^^^^^^^^^^^^^^^^^^^^^^^^^^^^^^^^
  File "/home/airflow/.local/lib/python3.12/site-packages/mlflow/store/tracking/rest_store.py", line 869, in get_experiment_by_name
    response_proto = self._call_endpoint(GetExperimentByName, req_body)
                     ^^^^^^^^^^^^^^^^^^^^^^^^^^^^^^^^^^^^^^^^^^^^^^^^^^
  File "/home/airflow/.local/lib/python3.12/site-packages/mlflow/store/tracking/rest_store.py", line 135, in _call_endpoint
    return call_endpoint(
           ^^^^^^^^^^^^^^
  File "/home/airflow/.local/lib/python3.12/site-packages/mlflow/utils/rest_utils.py", line 589, in call_endpoint
    response = http_request(**call_kwargs)
               ^^^^^^^^^^^^^^^^^^^^^^^^^^^
  File "/home/airflow/.local/lib/python3.12/site-packages/mlflow/utils/rest_utils.py", line 253, in http_request
    raise MlflowException(f"API request to {url} failed with exception {e}")
mlflow.exceptions.MlflowException: API request to http://mlflow-server:5500/api/2.0/mlflow/experiments/get-by-name failed with exception HTTPConnectionPool(host='mlflow-server', port=5500): Max retries exceeded with url: /api/2.0/mlflow/experiments/get-by-name?experiment_name=fraud_detection (Caused by NewConnectionError('<urllib3.connection.HTTPConnection object at 0x7be52e77cc20>: Failed to establish a new connection: [Errno 111] Connection refused'))

During handling of the above exception, another exception occurred:

Traceback (most recent call last):
  File "/home/airflow/.local/lib/python3.12/site-packages/airflow/models/taskinstance.py", line 768, in _execute_task
    result = _execute_callable(context=context, **execute_callable_kwargs)
             ^^^^^^^^^^^^^^^^^^^^^^^^^^^^^^^^^^^^^^^^^^^^^^^^^^^^^^^^^^^^^
  File "/home/airflow/.local/lib/python3.12/site-packages/airflow/models/taskinstance.py", line 734, in _execute_callable
    return ExecutionCallableRunner(
           ^^^^^^^^^^^^^^^^^^^^^^^^
  File "/home/airflow/.local/lib/python3.12/site-packages/airflow/utils/operator_helpers.py", line 252, in run
    return self.func(*args, **kwargs)
           ^^^^^^^^^^^^^^^^^^^^^^^^^^
  File "/home/airflow/.local/lib/python3.12/site-packages/airflow/models/baseoperator.py", line 424, in wrapper
    return func(self, *args, **kwargs)
           ^^^^^^^^^^^^^^^^^^^^^^^^^^^
  File "/home/airflow/.local/lib/python3.12/site-packages/airflow/operators/python.py", line 238, in execute
    return_value = self.execute_callable()
                   ^^^^^^^^^^^^^^^^^^^^^^^
  File "/home/airflow/.local/lib/python3.12/site-packages/airflow/operators/python.py", line 256, in execute_callable
    return runner.run(*self.op_args, **self.op_kwargs)
           ^^^^^^^^^^^^^^^^^^^^^^^^^^^^^^^^^^^^^^^^^^^
  File "/home/airflow/.local/lib/python3.12/site-packages/airflow/utils/operator_helpers.py", line 252, in run
    return self.func(*args, **kwargs)
           ^^^^^^^^^^^^^^^^^^^^^^^^^^
  File "/opt/airflow/dags/fraud_detection_training_dag.py", line 29, in _train_model
    raise AirflowException(f"Model Training failed: {str(e)}")
airflow.exceptions.AirflowException: Model Training failed: API request to http://mlflow-server:5500/api/2.0/mlflow/experiments/get-by-name failed with exception HTTPConnectionPool(host='mlflow-server', port=5500): Max retries exceeded with url: /api/2.0/mlflow/experiments/get-by-name?experiment_name=fraud_detection (Caused by NewConnectionError('<urllib3.connection.HTTPConnection object at 0x7be52e77cc20>: Failed to establish a new connection: [Errno 111] Connection refused'))
[2025-07-28T12:31:02.977+0000] {taskinstance.py:1226} INFO - Marking task as FAILED. dag_id=fraud_detection_training, task_id=execute_training, run_id=scheduled__2025-07-27T00:18:00+00:00, execution_date=20250727T001800, start_date=20250728T122644, end_date=20250728T123102
[2025-07-28T12:31:03.001+0000] {taskinstance.py:341} INFO - ::group::Post task execution logs
[2025-07-28T12:31:03.001+0000] {standard_task_runner.py:124} ERROR - Failed to execute job 4 for task execute_training (Model Training failed: API request to http://mlflow-server:5500/api/2.0/mlflow/experiments/get-by-name failed with exception HTTPConnectionPool(host='mlflow-server', port=5500): Max retries exceeded with url: /api/2.0/mlflow/experiments/get-by-name?experiment_name=fraud_detection (Caused by NewConnectionError('<urllib3.connection.HTTPConnection object at 0x7be52e77cc20>: Failed to establish a new connection: [Errno 111] Connection refused')); 91)
Traceback (most recent call last):
  File "/home/airflow/.local/lib/python3.12/site-packages/urllib3/connection.py", line 198, in _new_conn
    sock = connection.create_connection(
           ^^^^^^^^^^^^^^^^^^^^^^^^^^^^^
  File "/home/airflow/.local/lib/python3.12/site-packages/urllib3/util/connection.py", line 85, in create_connection
    raise err
  File "/home/airflow/.local/lib/python3.12/site-packages/urllib3/util/connection.py", line 73, in create_connection
    sock.connect(sa)
ConnectionRefusedError: [Errno 111] Connection refused

The above exception was the direct cause of the following exception:

Traceback (most recent call last):
  File "/home/airflow/.local/lib/python3.12/site-packages/urllib3/connectionpool.py", line 787, in urlopen
    response = self._make_request(
               ^^^^^^^^^^^^^^^^^^^
  File "/home/airflow/.local/lib/python3.12/site-packages/urllib3/connectionpool.py", line 493, in _make_request
    conn.request(
  File "/home/airflow/.local/lib/python3.12/site-packages/urllib3/connection.py", line 445, in request
    self.endheaders()
  File "/usr/local/lib/python3.12/http/client.py", line 1333, in endheaders
    self._send_output(message_body, encode_chunked=encode_chunked)
  File "/usr/local/lib/python3.12/http/client.py", line 1093, in _send_output
    self.send(msg)
  File "/usr/local/lib/python3.12/http/client.py", line 1037, in send
    self.connect()
  File "/home/airflow/.local/lib/python3.12/site-packages/urllib3/connection.py", line 276, in connect
    self.sock = self._new_conn()
                ^^^^^^^^^^^^^^^^
  File "/home/airflow/.local/lib/python3.12/site-packages/urllib3/connection.py", line 213, in _new_conn
    raise NewConnectionError(
urllib3.exceptions.NewConnectionError: <urllib3.connection.HTTPConnection object at 0x7be52e77cc20>: Failed to establish a new connection: [Errno 111] Connection refused

The above exception was the direct cause of the following exception:

Traceback (most recent call last):
  File "/home/airflow/.local/lib/python3.12/site-packages/requests/adapters.py", line 667, in send
    resp = conn.urlopen(
           ^^^^^^^^^^^^^
  File "/home/airflow/.local/lib/python3.12/site-packages/urllib3/connectionpool.py", line 871, in urlopen
    return self.urlopen(
           ^^^^^^^^^^^^^
  File "/home/airflow/.local/lib/python3.12/site-packages/urllib3/connectionpool.py", line 871, in urlopen
    return self.urlopen(
           ^^^^^^^^^^^^^
  File "/home/airflow/.local/lib/python3.12/site-packages/urllib3/connectionpool.py", line 871, in urlopen
    return self.urlopen(
           ^^^^^^^^^^^^^
  [Previous line repeated 4 more times]
  File "/home/airflow/.local/lib/python3.12/site-packages/urllib3/connectionpool.py", line 841, in urlopen
    retries = retries.increment(
              ^^^^^^^^^^^^^^^^^^
  File "/home/airflow/.local/lib/python3.12/site-packages/urllib3/util/retry.py", line 519, in increment
    raise MaxRetryError(_pool, url, reason) from reason  # type: ignore[arg-type]
    ^^^^^^^^^^^^^^^^^^^^^^^^^^^^^^^^^^^^^^^^^^^^^^^^^^^
urllib3.exceptions.MaxRetryError: HTTPConnectionPool(host='mlflow-server', port=5500): Max retries exceeded with url: /api/2.0/mlflow/experiments/get-by-name?experiment_name=fraud_detection (Caused by NewConnectionError('<urllib3.connection.HTTPConnection object at 0x7be52e77cc20>: Failed to establish a new connection: [Errno 111] Connection refused'))

During handling of the above exception, another exception occurred:

Traceback (most recent call last):
  File "/home/airflow/.local/lib/python3.12/site-packages/mlflow/utils/rest_utils.py", line 230, in http_request
    return _get_http_response_with_retries(
           ^^^^^^^^^^^^^^^^^^^^^^^^^^^^^^^^
  File "/home/airflow/.local/lib/python3.12/site-packages/mlflow/utils/request_utils.py", line 237, in _get_http_response_with_retries
    return session.request(method, url, allow_redirects=allow_redirects, **kwargs)
           ^^^^^^^^^^^^^^^^^^^^^^^^^^^^^^^^^^^^^^^^^^^^^^^^^^^^^^^^^^^^^^^^^^^^^^^
  File "/home/airflow/.local/lib/python3.12/site-packages/requests/sessions.py", line 589, in request
    resp = self.send(prep, **send_kwargs)
           ^^^^^^^^^^^^^^^^^^^^^^^^^^^^^^
  File "/home/airflow/.local/lib/python3.12/site-packages/requests/sessions.py", line 703, in send
    r = adapter.send(request, **kwargs)
        ^^^^^^^^^^^^^^^^^^^^^^^^^^^^^^^
  File "/home/airflow/.local/lib/python3.12/site-packages/requests/adapters.py", line 700, in send
    raise ConnectionError(e, request=request)
requests.exceptions.ConnectionError: HTTPConnectionPool(host='mlflow-server', port=5500): Max retries exceeded with url: /api/2.0/mlflow/experiments/get-by-name?experiment_name=fraud_detection (Caused by NewConnectionError('<urllib3.connection.HTTPConnection object at 0x7be52e77cc20>: Failed to establish a new connection: [Errno 111] Connection refused'))

During handling of the above exception, another exception occurred:

Traceback (most recent call last):
  File "/opt/airflow/dags/fraud_detection_training_dag.py", line 23, in _train_model
    trainer = FraudDetectionTraining()
              ^^^^^^^^^^^^^^^^^^^^^^^^
  File "/opt/airflow/dags/fraud_detection_training.py", line 55, in __init__
    mlflow.set_experiment(self.config['mlflow']['experiment_name'])
  File "/home/airflow/.local/lib/python3.12/site-packages/mlflow/tracking/fluent.py", line 183, in set_experiment
    experiment = client.get_experiment_by_name(experiment_name)
                 ^^^^^^^^^^^^^^^^^^^^^^^^^^^^^^^^^^^^^^^^^^^^^^
  File "/home/airflow/.local/lib/python3.12/site-packages/mlflow/tracking/_tracking_service/client.py", line 258, in get_experiment_by_name
    return self.store.get_experiment_by_name(name)
           ^^^^^^^^^^^^^^^^^^^^^^^^^^^^^^^^^^^^^^^
  File "/home/airflow/.local/lib/python3.12/site-packages/mlflow/store/tracking/rest_store.py", line 869, in get_experiment_by_name
    response_proto = self._call_endpoint(GetExperimentByName, req_body)
                     ^^^^^^^^^^^^^^^^^^^^^^^^^^^^^^^^^^^^^^^^^^^^^^^^^^
  File "/home/airflow/.local/lib/python3.12/site-packages/mlflow/store/tracking/rest_store.py", line 135, in _call_endpoint
    return call_endpoint(
           ^^^^^^^^^^^^^^
  File "/home/airflow/.local/lib/python3.12/site-packages/mlflow/utils/rest_utils.py", line 589, in call_endpoint
    response = http_request(**call_kwargs)
               ^^^^^^^^^^^^^^^^^^^^^^^^^^^
  File "/home/airflow/.local/lib/python3.12/site-packages/mlflow/utils/rest_utils.py", line 253, in http_request
    raise MlflowException(f"API request to {url} failed with exception {e}")
mlflow.exceptions.MlflowException: API request to http://mlflow-server:5500/api/2.0/mlflow/experiments/get-by-name failed with exception HTTPConnectionPool(host='mlflow-server', port=5500): Max retries exceeded with url: /api/2.0/mlflow/experiments/get-by-name?experiment_name=fraud_detection (Caused by NewConnectionError('<urllib3.connection.HTTPConnection object at 0x7be52e77cc20>: Failed to establish a new connection: [Errno 111] Connection refused'))

During handling of the above exception, another exception occurred:

Traceback (most recent call last):
  File "/home/airflow/.local/lib/python3.12/site-packages/airflow/task/task_runner/standard_task_runner.py", line 117, in _start_by_fork
    ret = args.func(args, dag=self.dag)
          ^^^^^^^^^^^^^^^^^^^^^^^^^^^^^
  File "/home/airflow/.local/lib/python3.12/site-packages/airflow/cli/cli_config.py", line 49, in command
    return func(*args, **kwargs)
           ^^^^^^^^^^^^^^^^^^^^^
  File "/home/airflow/.local/lib/python3.12/site-packages/airflow/utils/cli.py", line 116, in wrapper
    return f(*args, **kwargs)
           ^^^^^^^^^^^^^^^^^^
  File "/home/airflow/.local/lib/python3.12/site-packages/airflow/cli/commands/task_command.py", line 483, in task_run
    task_return_code = _run_task_by_selected_method(args, _dag, ti)
                       ^^^^^^^^^^^^^^^^^^^^^^^^^^^^^^^^^^^^^^^^^^^^
  File "/home/airflow/.local/lib/python3.12/site-packages/airflow/cli/commands/task_command.py", line 256, in _run_task_by_selected_method
    return _run_raw_task(args, ti)
           ^^^^^^^^^^^^^^^^^^^^^^^
  File "/home/airflow/.local/lib/python3.12/site-packages/airflow/cli/commands/task_command.py", line 341, in _run_raw_task
    return ti._run_raw_task(
           ^^^^^^^^^^^^^^^^^
  File "/home/airflow/.local/lib/python3.12/site-packages/airflow/utils/session.py", line 97, in wrapper
    return func(*args, session=session, **kwargs)
           ^^^^^^^^^^^^^^^^^^^^^^^^^^^^^^^^^^^^^^
  File "/home/airflow/.local/lib/python3.12/site-packages/airflow/models/taskinstance.py", line 3006, in _run_raw_task
    return _run_raw_task(
           ^^^^^^^^^^^^^^
  File "/home/airflow/.local/lib/python3.12/site-packages/airflow/models/taskinstance.py", line 274, in _run_raw_task
    TaskInstance._execute_task_with_callbacks(
  File "/home/airflow/.local/lib/python3.12/site-packages/airflow/models/taskinstance.py", line 3161, in _execute_task_with_callbacks
    result = self._execute_task(context, task_orig)
             ^^^^^^^^^^^^^^^^^^^^^^^^^^^^^^^^^^^^^^
  File "/home/airflow/.local/lib/python3.12/site-packages/airflow/models/taskinstance.py", line 3185, in _execute_task
    return _execute_task(self, context, task_orig)
           ^^^^^^^^^^^^^^^^^^^^^^^^^^^^^^^^^^^^^^^
  File "/home/airflow/.local/lib/python3.12/site-packages/airflow/models/taskinstance.py", line 768, in _execute_task
    result = _execute_callable(context=context, **execute_callable_kwargs)
             ^^^^^^^^^^^^^^^^^^^^^^^^^^^^^^^^^^^^^^^^^^^^^^^^^^^^^^^^^^^^^
  File "/home/airflow/.local/lib/python3.12/site-packages/airflow/models/taskinstance.py", line 734, in _execute_callable
    return ExecutionCallableRunner(
           ^^^^^^^^^^^^^^^^^^^^^^^^
  File "/home/airflow/.local/lib/python3.12/site-packages/airflow/utils/operator_helpers.py", line 252, in run
    return self.func(*args, **kwargs)
           ^^^^^^^^^^^^^^^^^^^^^^^^^^
  File "/home/airflow/.local/lib/python3.12/site-packages/airflow/models/baseoperator.py", line 424, in wrapper
    return func(self, *args, **kwargs)
           ^^^^^^^^^^^^^^^^^^^^^^^^^^^
  File "/home/airflow/.local/lib/python3.12/site-packages/airflow/operators/python.py", line 238, in execute
    return_value = self.execute_callable()
                   ^^^^^^^^^^^^^^^^^^^^^^^
  File "/home/airflow/.local/lib/python3.12/site-packages/airflow/operators/python.py", line 256, in execute_callable
    return runner.run(*self.op_args, **self.op_kwargs)
           ^^^^^^^^^^^^^^^^^^^^^^^^^^^^^^^^^^^^^^^^^^^
  File "/home/airflow/.local/lib/python3.12/site-packages/airflow/utils/operator_helpers.py", line 252, in run
    return self.func(*args, **kwargs)
           ^^^^^^^^^^^^^^^^^^^^^^^^^^
  File "/opt/airflow/dags/fraud_detection_training_dag.py", line 29, in _train_model
    raise AirflowException(f"Model Training failed: {str(e)}")
airflow.exceptions.AirflowException: Model Training failed: API request to http://mlflow-server:5500/api/2.0/mlflow/experiments/get-by-name failed with exception HTTPConnectionPool(host='mlflow-server', port=5500): Max retries exceeded with url: /api/2.0/mlflow/experiments/get-by-name?experiment_name=fraud_detection (Caused by NewConnectionError('<urllib3.connection.HTTPConnection object at 0x7be52e77cc20>: Failed to establish a new connection: [Errno 111] Connection refused'))
[2025-07-28T12:31:03.036+0000] {local_task_job_runner.py:266} INFO - Task exited with return code 1
[2025-07-28T12:31:03.054+0000] {taskinstance.py:3901} INFO - 1 downstream tasks scheduled from follow-on schedule check
[2025-07-28T12:31:03.055+0000] {local_task_job_runner.py:245} INFO - ::endgroup::
