[2025-08-03T02:27:29.450+0000] {local_task_job_runner.py:123} INFO - ::group::Pre task execution logs
[2025-08-03T02:27:29.469+0000] {taskinstance.py:2614} INFO - Dependencies all met for dep_context=non-requeueable deps ti=<TaskInstance: fraud_detection_training.execute_training scheduled__2025-07-30T00:18:00+00:00 [queued]>
[2025-08-03T02:27:29.477+0000] {taskinstance.py:2614} INFO - Dependencies all met for dep_context=requeueable deps ti=<TaskInstance: fraud_detection_training.execute_training scheduled__2025-07-30T00:18:00+00:00 [queued]>
[2025-08-03T02:27:29.478+0000] {taskinstance.py:2867} INFO - Starting attempt 1 of 1
[2025-08-03T02:27:29.488+0000] {taskinstance.py:2890} INFO - Executing <Task(PythonOperator): execute_training> on 2025-07-30 00:18:00+00:00
[2025-08-03T02:27:29.494+0000] {warnings.py:112} WARNING - /home/***/.local/lib/python3.12/site-packages/***/task/task_runner/standard_task_runner.py:70: DeprecationWarning: This process (pid=91) is multi-threaded, use of fork() may lead to deadlocks in the child.
  pid = os.fork()

[2025-08-03T02:27:29.496+0000] {standard_task_runner.py:72} INFO - Started process 92 to run task
[2025-08-03T02:27:29.496+0000] {standard_task_runner.py:104} INFO - Running: ['***', 'tasks', 'run', 'fraud_detection_training', 'execute_training', 'scheduled__2025-07-30T00:18:00+00:00', '--job-id', '106', '--raw', '--subdir', 'DAGS_FOLDER/fraud_detection_training_dag.py', '--cfg-path', '/tmp/tmpqg7j90ca']
[2025-08-03T02:27:29.497+0000] {standard_task_runner.py:105} INFO - Job 106: Subtask execute_training
[2025-08-03T02:27:29.539+0000] {task_command.py:467} INFO - Running <TaskInstance: fraud_detection_training.execute_training scheduled__2025-07-30T00:18:00+00:00 [running]> on host 18c2fa2af852
[2025-08-03T02:27:29.618+0000] {taskinstance.py:3134} INFO - Exporting env vars: AIRFLOW_CTX_DAG_OWNER='kanewyp' AIRFLOW_CTX_DAG_ID='fraud_detection_training' AIRFLOW_CTX_TASK_ID='execute_training' AIRFLOW_CTX_EXECUTION_DATE='2025-07-30T00:18:00+00:00' AIRFLOW_CTX_TRY_NUMBER='1' AIRFLOW_CTX_DAG_RUN_ID='scheduled__2025-07-30T00:18:00+00:00'
[2025-08-03T02:27:29.619+0000] {taskinstance.py:732} INFO - ::endgroup::
[2025-08-03T02:27:34.058+0000] {font_manager.py:1639} INFO - generated new fontManager
[2025-08-03T02:27:34.264+0000] {fraud_detection_training_dag.py:22} INFO - Initializing Fraud Detection Training
[2025-08-03T02:27:34.274+0000] {fraud_detection_training.py:64} INFO - Configuration loaded successfully
[2025-08-03T02:27:34.818+0000] {fraud_detection_training.py:90} INFO - Connected to MinIO. Available buckets: mlflow
[2025-08-03T02:27:35.429+0000] {fraud_detection_training.py:184} INFO - Starting model training process...
[2025-08-03T02:27:35.429+0000] {fraud_detection_training.py:106} INFO - Reading data from Kafka topic: transactions
[2025-08-03T02:27:35.589+0000] {conn.py:396} INFO - <BrokerConnection client_id=kafka-python-2.2.15, node_id=bootstrap-0 host=pkc-ldvj1.ap-southeast-2.aws.confluent.cloud:9092 <connecting> [IPv4 ('13.237.143.76', 9092)]>: connecting to pkc-ldvj1.ap-southeast-2.aws.confluent.cloud:9092 [('13.237.143.76', 9092) IPv4]
[2025-08-03T02:27:35.637+0000] {conn.py:497} INFO - <BrokerConnection client_id=kafka-python-2.2.15, node_id=bootstrap-0 host=pkc-ldvj1.ap-southeast-2.aws.confluent.cloud:9092 <handshake> [IPv4 ('13.237.143.76', 9092)]>: Loading system default SSL CAs from ('/usr/lib/ssl/cert.pem', '/usr/lib/ssl/certs', 'SSL_CERT_FILE', '/usr/lib/ssl/cert.pem', 'SSL_CERT_DIR', '/usr/lib/ssl/certs')
[2025-08-03T02:27:35.793+0000] {conn.py:618} INFO - <BrokerConnection client_id=kafka-python-2.2.15, node_id=bootstrap-0 host=pkc-ldvj1.ap-southeast-2.aws.confluent.cloud:9092 <checking_api_versions_recv> [IPv4 ('13.237.143.76', 9092)]>: Broker version identified as 2.6
[2025-08-03T02:27:35.961+0000] {conn.py:822} INFO - <BrokerConnection client_id=kafka-python-2.2.15, node_id=bootstrap-0 host=pkc-ldvj1.ap-southeast-2.aws.confluent.cloud:9092 <authenticating> [IPv4 ('13.237.143.76', 9092)]>: Authenticated as KQIWVOLDBVJZDLTP via SASL / Plain
[2025-08-03T02:27:35.962+0000] {conn.py:467} INFO - <BrokerConnection client_id=kafka-python-2.2.15, node_id=bootstrap-0 host=pkc-ldvj1.ap-southeast-2.aws.confluent.cloud:9092 <connected> [IPv4 ('13.237.143.76', 9092)]>: Connection complete.
[2025-08-03T02:27:35.963+0000] {consumer.py:120} WARNING - group_id is None: disabling auto-commit.
[2025-08-03T02:27:35.963+0000] {subscription_state.py:181} INFO - Updating subscribed topics to: ('transactions',)
[2025-08-03T02:27:36.002+0000] {subscription_state.py:254} INFO - Updated partition assignment: [('transactions', 0)]
[2025-08-03T02:27:36.092+0000] {conn.py:396} INFO - <BrokerConnection client_id=kafka-python-2.2.15, node_id=0 host=b0-pkc-ldvj1.ap-southeast-2.aws.confluent.cloud:9092 <connecting> [IPv4 ('13.236.79.131', 9092)]>: connecting to b0-pkc-ldvj1.ap-southeast-2.aws.confluent.cloud:9092 [('13.236.79.131', 9092) IPv4]
[2025-08-03T02:27:36.140+0000] {conn.py:497} INFO - <BrokerConnection client_id=kafka-python-2.2.15, node_id=0 host=b0-pkc-ldvj1.ap-southeast-2.aws.confluent.cloud:9092 <handshake> [IPv4 ('13.236.79.131', 9092)]>: Loading system default SSL CAs from ('/usr/lib/ssl/cert.pem', '/usr/lib/ssl/certs', 'SSL_CERT_FILE', '/usr/lib/ssl/cert.pem', 'SSL_CERT_DIR', '/usr/lib/ssl/certs')
[2025-08-03T02:27:36.318+0000] {conn.py:822} INFO - <BrokerConnection client_id=kafka-python-2.2.15, node_id=0 host=b0-pkc-ldvj1.ap-southeast-2.aws.confluent.cloud:9092 <authenticating> [IPv4 ('13.236.79.131', 9092)]>: Authenticated as KQIWVOLDBVJZDLTP via SASL / Plain
[2025-08-03T02:27:36.319+0000] {conn.py:467} INFO - <BrokerConnection client_id=kafka-python-2.2.15, node_id=0 host=b0-pkc-ldvj1.ap-southeast-2.aws.confluent.cloud:9092 <connected> [IPv4 ('13.236.79.131', 9092)]>: Connection complete.
[2025-08-03T02:27:36.319+0000] {conn.py:945} INFO - <BrokerConnection client_id=kafka-python-2.2.15, node_id=bootstrap-0 host=pkc-ldvj1.ap-southeast-2.aws.confluent.cloud:9092 <connected> [IPv4 ('13.237.143.76', 9092)]>: Closing connection. 
[2025-08-03T02:27:36.362+0000] {fetcher.py:418} INFO - Resetting offset for partition ('transactions', 0) to offset 0.
[2025-08-03T02:27:59.124+0000] {conn.py:945} INFO - <BrokerConnection client_id=kafka-python-2.2.15, node_id=0 host=b0-pkc-ldvj1.ap-southeast-2.aws.confluent.cloud:9092 <connected> [IPv4 ('13.236.79.131', 9092)]>: Closing connection. 
[2025-08-03T02:27:59.125+0000] {fetcher.py:786} INFO - Fetch to node 0 failed: Cancelled: <BrokerConnection client_id=kafka-python-2.2.15, node_id=0 host=b0-pkc-ldvj1.ap-southeast-2.aws.confluent.cloud:9092 <connected> [IPv4 ('13.236.79.131', 9092)]>
[2025-08-03T02:27:59.508+0000] {fraud_detection_training.py:133} INFO - Received 99372 records from Kafka with fraud rate: 0.73%
[2025-08-03T02:28:09.941+0000] {fraud_detection_training.py:263} INFO - Starting hyperparameter tuning...
[2025-08-03T05:23:12.602+0000] {job.py:229} INFO - Heartbeat recovered after 5565.18 seconds
[2025-08-03T05:48:36.430+0000] {job.py:229} INFO - Heartbeat recovered after 1523.83 seconds
[2025-08-03T06:13:13.729+0000] {fraud_detection_training.py:267} INFO - Best hyperparameters found: {'classifier__subsample': 0.6, 'classifier__reg_alpha': 0, 'classifier__max_depth': 3, 'classifier__learning_rate': 0.01, 'classifier__gamma': 0.1, 'classifier__colsample_bytree': 0.6}
[2025-08-03T06:13:14.012+0000] {fraud_detection_training.py:273} INFO - Best threshold for F1 score: 0.8671025037765503
[2025-08-03T06:13:18.948+0000] {credentials.py:1147} INFO - Found credentials in environment variables.
[2025-08-03T06:13:19.662+0000] {warnings.py:112} WARNING - /home/***/.local/lib/python3.12/site-packages/mlflow/types/utils.py:452: UserWarning: Hint: Inferred schema contains integer column(s). Integer columns in Python cannot represent missing values. If your input data contains missing values at inference time, it will be encoded as floats and will cause a schema enforcement error. The best way to avoid this problem is to infer the model schema based on a realistic data sample (training dataset) that includes missing values. Alternatively, you can declare integer columns as doubles (float64) whenever these columns may have missing values. See `Handling Integers With Missing Values <https://www.mlflow.org/docs/latest/models.html#handling-integers-with-missing-values>`_ for more details.
  warnings.warn(

[2025-08-03T06:13:19.719+0000] {logging_mixin.py:190} WARNING - 2025/08/03 06:13:19 WARNING mlflow.models.model: `artifact_path` is deprecated. Please use `name` instead.
[2025-08-03T06:13:32.404+0000] {logging_mixin.py:190} WARNING - Registered model 'fraud_detection_model' already exists. Creating a new version of this model...
[2025-08-03T06:13:32.493+0000] {logging_mixin.py:190} WARNING - 2025/08/03 06:13:32 INFO mlflow.store.model_registry.abstract_store: Waiting up to 300 seconds for model version to finish creation. Model name: fraud_detection_model, version 3
[2025-08-03T06:13:32.493+0000] {logging_mixin.py:190} WARNING - Created version '3' of model 'fraud_detection_model'.
[2025-08-03T06:13:32.560+0000] {logging_mixin.py:190} INFO - üèÉ View run clean-duck-957 at: http://mlflow-server:5500/#/experiments/1/runs/43ef6098d6e5425bac5b31b8f4412723
[2025-08-03T06:13:32.560+0000] {logging_mixin.py:190} INFO - üß™ View experiment at: http://mlflow-server:5500/#/experiments/1
[2025-08-03T06:13:32.578+0000] {fraud_detection_training.py:340} ERROR - Training failed: [Errno 13] Permission denied: '/app/models/fraud_detection_model.pkl'
Traceback (most recent call last):
  File "/opt/airflow/dags/fraud_detection_training.py", line 333, in train_model
    joblib.dump(best_model, '/app/models/fraud_detection_model.pkl')
  File "/home/airflow/.local/lib/python3.12/site-packages/joblib/numpy_pickle.py", line 599, in dump
    with open(filename, "wb") as f:
         ^^^^^^^^^^^^^^^^^^^^
PermissionError: [Errno 13] Permission denied: '/app/models/fraud_detection_model.pkl'
[2025-08-03T06:13:32.584+0000] {fraud_detection_training_dag.py:28} ERROR - Training failed: [Errno 13] Permission denied: '/app/models/fraud_detection_model.pkl'
Traceback (most recent call last):
  File "/opt/airflow/dags/fraud_detection_training_dag.py", line 24, in _train_model
    model, precision = trainer.train_model()
                       ^^^^^^^^^^^^^^^^^^^^^
  File "/opt/airflow/dags/fraud_detection_training.py", line 333, in train_model
    joblib.dump(best_model, '/app/models/fraud_detection_model.pkl')
  File "/home/airflow/.local/lib/python3.12/site-packages/joblib/numpy_pickle.py", line 599, in dump
    with open(filename, "wb") as f:
         ^^^^^^^^^^^^^^^^^^^^
PermissionError: [Errno 13] Permission denied: '/app/models/fraud_detection_model.pkl'
[2025-08-03T06:13:32.747+0000] {taskinstance.py:3313} ERROR - Task failed with exception
Traceback (most recent call last):
  File "/opt/airflow/dags/fraud_detection_training_dag.py", line 24, in _train_model
    model, precision = trainer.train_model()
                       ^^^^^^^^^^^^^^^^^^^^^
  File "/opt/airflow/dags/fraud_detection_training.py", line 333, in train_model
    joblib.dump(best_model, '/app/models/fraud_detection_model.pkl')
  File "/home/airflow/.local/lib/python3.12/site-packages/joblib/numpy_pickle.py", line 599, in dump
    with open(filename, "wb") as f:
         ^^^^^^^^^^^^^^^^^^^^
PermissionError: [Errno 13] Permission denied: '/app/models/fraud_detection_model.pkl'

During handling of the above exception, another exception occurred:

Traceback (most recent call last):
  File "/home/airflow/.local/lib/python3.12/site-packages/airflow/models/taskinstance.py", line 768, in _execute_task
    result = _execute_callable(context=context, **execute_callable_kwargs)
             ^^^^^^^^^^^^^^^^^^^^^^^^^^^^^^^^^^^^^^^^^^^^^^^^^^^^^^^^^^^^^
  File "/home/airflow/.local/lib/python3.12/site-packages/airflow/models/taskinstance.py", line 734, in _execute_callable
    return ExecutionCallableRunner(
           ^^^^^^^^^^^^^^^^^^^^^^^^
  File "/home/airflow/.local/lib/python3.12/site-packages/airflow/utils/operator_helpers.py", line 252, in run
    return self.func(*args, **kwargs)
           ^^^^^^^^^^^^^^^^^^^^^^^^^^
  File "/home/airflow/.local/lib/python3.12/site-packages/airflow/models/baseoperator.py", line 424, in wrapper
    return func(self, *args, **kwargs)
           ^^^^^^^^^^^^^^^^^^^^^^^^^^^
  File "/home/airflow/.local/lib/python3.12/site-packages/airflow/operators/python.py", line 238, in execute
    return_value = self.execute_callable()
                   ^^^^^^^^^^^^^^^^^^^^^^^
  File "/home/airflow/.local/lib/python3.12/site-packages/airflow/operators/python.py", line 256, in execute_callable
    return runner.run(*self.op_args, **self.op_kwargs)
           ^^^^^^^^^^^^^^^^^^^^^^^^^^^^^^^^^^^^^^^^^^^
  File "/home/airflow/.local/lib/python3.12/site-packages/airflow/utils/operator_helpers.py", line 252, in run
    return self.func(*args, **kwargs)
           ^^^^^^^^^^^^^^^^^^^^^^^^^^
  File "/opt/airflow/dags/fraud_detection_training_dag.py", line 29, in _train_model
    raise AirflowException(f"Model Training failed: {str(e)}")
airflow.exceptions.AirflowException: Model Training failed: [Errno 13] Permission denied: '/app/models/fraud_detection_model.pkl'
[2025-08-03T06:13:32.769+0000] {taskinstance.py:1226} INFO - Marking task as FAILED. dag_id=fraud_detection_training, task_id=execute_training, run_id=scheduled__2025-07-30T00:18:00+00:00, execution_date=20250730T001800, start_date=20250803T022729, end_date=20250803T061332
[2025-08-03T06:13:32.879+0000] {taskinstance.py:341} INFO - ::group::Post task execution logs
[2025-08-03T06:13:32.883+0000] {standard_task_runner.py:124} ERROR - Failed to execute job 106 for task execute_training (Model Training failed: [Errno 13] Permission denied: '/app/models/fraud_detection_model.pkl'; 92)
Traceback (most recent call last):
  File "/opt/airflow/dags/fraud_detection_training_dag.py", line 24, in _train_model
    model, precision = trainer.train_model()
                       ^^^^^^^^^^^^^^^^^^^^^
  File "/opt/airflow/dags/fraud_detection_training.py", line 333, in train_model
    joblib.dump(best_model, '/app/models/fraud_detection_model.pkl')
  File "/home/airflow/.local/lib/python3.12/site-packages/joblib/numpy_pickle.py", line 599, in dump
    with open(filename, "wb") as f:
         ^^^^^^^^^^^^^^^^^^^^
PermissionError: [Errno 13] Permission denied: '/app/models/fraud_detection_model.pkl'

During handling of the above exception, another exception occurred:

Traceback (most recent call last):
  File "/home/airflow/.local/lib/python3.12/site-packages/airflow/task/task_runner/standard_task_runner.py", line 117, in _start_by_fork
    ret = args.func(args, dag=self.dag)
          ^^^^^^^^^^^^^^^^^^^^^^^^^^^^^
  File "/home/airflow/.local/lib/python3.12/site-packages/airflow/cli/cli_config.py", line 49, in command
    return func(*args, **kwargs)
           ^^^^^^^^^^^^^^^^^^^^^
  File "/home/airflow/.local/lib/python3.12/site-packages/airflow/utils/cli.py", line 116, in wrapper
    return f(*args, **kwargs)
           ^^^^^^^^^^^^^^^^^^
  File "/home/airflow/.local/lib/python3.12/site-packages/airflow/cli/commands/task_command.py", line 483, in task_run
    task_return_code = _run_task_by_selected_method(args, _dag, ti)
                       ^^^^^^^^^^^^^^^^^^^^^^^^^^^^^^^^^^^^^^^^^^^^
  File "/home/airflow/.local/lib/python3.12/site-packages/airflow/cli/commands/task_command.py", line 256, in _run_task_by_selected_method
    return _run_raw_task(args, ti)
           ^^^^^^^^^^^^^^^^^^^^^^^
  File "/home/airflow/.local/lib/python3.12/site-packages/airflow/cli/commands/task_command.py", line 341, in _run_raw_task
    return ti._run_raw_task(
           ^^^^^^^^^^^^^^^^^
  File "/home/airflow/.local/lib/python3.12/site-packages/airflow/utils/session.py", line 97, in wrapper
    return func(*args, session=session, **kwargs)
           ^^^^^^^^^^^^^^^^^^^^^^^^^^^^^^^^^^^^^^
  File "/home/airflow/.local/lib/python3.12/site-packages/airflow/models/taskinstance.py", line 3006, in _run_raw_task
    return _run_raw_task(
           ^^^^^^^^^^^^^^
  File "/home/airflow/.local/lib/python3.12/site-packages/airflow/models/taskinstance.py", line 274, in _run_raw_task
    TaskInstance._execute_task_with_callbacks(
  File "/home/airflow/.local/lib/python3.12/site-packages/airflow/models/taskinstance.py", line 3161, in _execute_task_with_callbacks
    result = self._execute_task(context, task_orig)
             ^^^^^^^^^^^^^^^^^^^^^^^^^^^^^^^^^^^^^^
  File "/home/airflow/.local/lib/python3.12/site-packages/airflow/models/taskinstance.py", line 3185, in _execute_task
    return _execute_task(self, context, task_orig)
           ^^^^^^^^^^^^^^^^^^^^^^^^^^^^^^^^^^^^^^^
  File "/home/airflow/.local/lib/python3.12/site-packages/airflow/models/taskinstance.py", line 768, in _execute_task
    result = _execute_callable(context=context, **execute_callable_kwargs)
             ^^^^^^^^^^^^^^^^^^^^^^^^^^^^^^^^^^^^^^^^^^^^^^^^^^^^^^^^^^^^^
  File "/home/airflow/.local/lib/python3.12/site-packages/airflow/models/taskinstance.py", line 734, in _execute_callable
    return ExecutionCallableRunner(
           ^^^^^^^^^^^^^^^^^^^^^^^^
  File "/home/airflow/.local/lib/python3.12/site-packages/airflow/utils/operator_helpers.py", line 252, in run
    return self.func(*args, **kwargs)
           ^^^^^^^^^^^^^^^^^^^^^^^^^^
  File "/home/airflow/.local/lib/python3.12/site-packages/airflow/models/baseoperator.py", line 424, in wrapper
    return func(self, *args, **kwargs)
           ^^^^^^^^^^^^^^^^^^^^^^^^^^^
  File "/home/airflow/.local/lib/python3.12/site-packages/airflow/operators/python.py", line 238, in execute
    return_value = self.execute_callable()
                   ^^^^^^^^^^^^^^^^^^^^^^^
  File "/home/airflow/.local/lib/python3.12/site-packages/airflow/operators/python.py", line 256, in execute_callable
    return runner.run(*self.op_args, **self.op_kwargs)
           ^^^^^^^^^^^^^^^^^^^^^^^^^^^^^^^^^^^^^^^^^^^
  File "/home/airflow/.local/lib/python3.12/site-packages/airflow/utils/operator_helpers.py", line 252, in run
    return self.func(*args, **kwargs)
           ^^^^^^^^^^^^^^^^^^^^^^^^^^
  File "/opt/airflow/dags/fraud_detection_training_dag.py", line 29, in _train_model
    raise AirflowException(f"Model Training failed: {str(e)}")
airflow.exceptions.AirflowException: Model Training failed: [Errno 13] Permission denied: '/app/models/fraud_detection_model.pkl'
[2025-08-03T06:13:32.974+0000] {local_task_job_runner.py:266} INFO - Task exited with return code 1
[2025-08-03T06:13:33.212+0000] {taskinstance.py:3901} INFO - 1 downstream tasks scheduled from follow-on schedule check
[2025-08-03T06:13:33.214+0000] {local_task_job_runner.py:245} INFO - ::endgroup::
