[2025-07-30T05:48:07.420+0000] {local_task_job_runner.py:123} INFO - ::group::Pre task execution logs
[2025-07-30T05:48:07.438+0000] {taskinstance.py:2614} INFO - Dependencies all met for dep_context=non-requeueable deps ti=<TaskInstance: fraud_detection_training.execute_training manual__2025-07-30T05:48:05.513630+00:00 [queued]>
[2025-07-30T05:48:07.447+0000] {taskinstance.py:2614} INFO - Dependencies all met for dep_context=requeueable deps ti=<TaskInstance: fraud_detection_training.execute_training manual__2025-07-30T05:48:05.513630+00:00 [queued]>
[2025-07-30T05:48:07.447+0000] {taskinstance.py:2867} INFO - Starting attempt 1 of 1
[2025-07-30T05:48:07.458+0000] {taskinstance.py:2890} INFO - Executing <Task(PythonOperator): execute_training> on 2025-07-30 05:48:05.513630+00:00
[2025-07-30T05:48:07.463+0000] {warnings.py:112} WARNING - /home/***/.local/lib/python3.12/site-packages/***/task/task_runner/standard_task_runner.py:70: DeprecationWarning: This process (pid=1552) is multi-threaded, use of fork() may lead to deadlocks in the child.
  pid = os.fork()

[2025-07-30T05:48:07.464+0000] {standard_task_runner.py:72} INFO - Started process 1553 to run task
[2025-07-30T05:48:07.465+0000] {standard_task_runner.py:104} INFO - Running: ['***', 'tasks', 'run', 'fraud_detection_training', 'execute_training', 'manual__2025-07-30T05:48:05.513630+00:00', '--job-id', '93', '--raw', '--subdir', 'DAGS_FOLDER/fraud_detection_training_dag.py', '--cfg-path', '/tmp/tmp2dcs7ktk']
[2025-07-30T05:48:07.466+0000] {standard_task_runner.py:105} INFO - Job 93: Subtask execute_training
[2025-07-30T05:48:07.507+0000] {task_command.py:467} INFO - Running <TaskInstance: fraud_detection_training.execute_training manual__2025-07-30T05:48:05.513630+00:00 [running]> on host ee095bff1d61
[2025-07-30T05:48:07.576+0000] {taskinstance.py:3134} INFO - Exporting env vars: AIRFLOW_CTX_DAG_OWNER='kanewyp' AIRFLOW_CTX_DAG_ID='fraud_detection_training' AIRFLOW_CTX_TASK_ID='execute_training' AIRFLOW_CTX_EXECUTION_DATE='2025-07-30T05:48:05.513630+00:00' AIRFLOW_CTX_TRY_NUMBER='1' AIRFLOW_CTX_DAG_RUN_ID='manual__2025-07-30T05:48:05.513630+00:00'
[2025-07-30T05:48:07.577+0000] {taskinstance.py:732} INFO - ::endgroup::
[2025-07-30T05:48:12.548+0000] {fraud_detection_training_dag.py:22} INFO - Initializing Fraud Detection Training
[2025-07-30T05:48:12.562+0000] {fraud_detection_training.py:64} INFO - Configuration loaded successfully
[2025-07-30T05:48:13.290+0000] {fraud_detection_training.py:90} INFO - Connected to MinIO. Available buckets: mlflow
[2025-07-30T05:48:13.434+0000] {fraud_detection_training.py:184} INFO - Starting model training process...
[2025-07-30T05:48:13.435+0000] {fraud_detection_training.py:106} INFO - Reading data from Kafka topic: transactions
[2025-07-30T05:48:13.618+0000] {conn.py:396} INFO - <BrokerConnection client_id=kafka-python-2.2.15, node_id=bootstrap-0 host=pkc-ldvj1.ap-southeast-2.aws.confluent.cloud:9092 <connecting> [IPv4 ('52.64.27.176', 9092)]>: connecting to pkc-ldvj1.ap-southeast-2.aws.confluent.cloud:9092 [('52.64.27.176', 9092) IPv4]
[2025-07-30T05:48:14.713+0000] {conn.py:497} INFO - <BrokerConnection client_id=kafka-python-2.2.15, node_id=bootstrap-0 host=pkc-ldvj1.ap-southeast-2.aws.confluent.cloud:9092 <handshake> [IPv4 ('52.64.27.176', 9092)]>: Loading system default SSL CAs from ('/usr/lib/ssl/cert.pem', '/usr/lib/ssl/certs', 'SSL_CERT_FILE', '/usr/lib/ssl/cert.pem', 'SSL_CERT_DIR', '/usr/lib/ssl/certs')
[2025-07-30T05:48:14.979+0000] {conn.py:618} INFO - <BrokerConnection client_id=kafka-python-2.2.15, node_id=bootstrap-0 host=pkc-ldvj1.ap-southeast-2.aws.confluent.cloud:9092 <checking_api_versions_recv> [IPv4 ('52.64.27.176', 9092)]>: Broker version identified as 2.6
[2025-07-30T05:48:15.159+0000] {conn.py:822} INFO - <BrokerConnection client_id=kafka-python-2.2.15, node_id=bootstrap-0 host=pkc-ldvj1.ap-southeast-2.aws.confluent.cloud:9092 <authenticating> [IPv4 ('52.64.27.176', 9092)]>: Authenticated as KQIWVOLDBVJZDLTP via SASL / Plain
[2025-07-30T05:48:15.160+0000] {conn.py:467} INFO - <BrokerConnection client_id=kafka-python-2.2.15, node_id=bootstrap-0 host=pkc-ldvj1.ap-southeast-2.aws.confluent.cloud:9092 <connected> [IPv4 ('52.64.27.176', 9092)]>: Connection complete.
[2025-07-30T05:48:15.161+0000] {consumer.py:120} WARNING - group_id is None: disabling auto-commit.
[2025-07-30T05:48:15.162+0000] {subscription_state.py:181} INFO - Updating subscribed topics to: ('transactions',)
[2025-07-30T05:48:15.202+0000] {subscription_state.py:254} INFO - Updated partition assignment: [('transactions', 0)]
[2025-07-30T05:48:15.289+0000] {conn.py:396} INFO - <BrokerConnection client_id=kafka-python-2.2.15, node_id=0 host=b0-pkc-ldvj1.ap-southeast-2.aws.confluent.cloud:9092 <connecting> [IPv4 ('13.236.79.131', 9092)]>: connecting to b0-pkc-ldvj1.ap-southeast-2.aws.confluent.cloud:9092 [('13.236.79.131', 9092) IPv4]
[2025-07-30T05:48:25.162+0000] {conn.py:945} INFO - <BrokerConnection client_id=kafka-python-2.2.15, node_id=bootstrap-0 host=pkc-ldvj1.ap-southeast-2.aws.confluent.cloud:9092 <connected> [IPv4 ('52.64.27.176', 9092)]>: Closing connection. 
[2025-07-30T05:48:25.164+0000] {conn.py:945} INFO - <BrokerConnection client_id=kafka-python-2.2.15, node_id=0 host=b0-pkc-ldvj1.ap-southeast-2.aws.confluent.cloud:9092 <connecting> [IPv4 ('13.236.79.131', 9092)]>: Closing connection. 
[2025-07-30T05:48:25.184+0000] {fraud_detection_training.py:137} ERROR - Failed to read data from Kafka: No message received from Kafka
Traceback (most recent call last):
  File "/opt/airflow/dags/fraud_detection_training.py", line 125, in _read_data_from_kafka
    raise ValueError('No message received from Kafka')
ValueError: No message received from Kafka
[2025-07-30T05:48:25.187+0000] {fraud_detection_training.py:340} ERROR - Training failed: No message received from Kafka
Traceback (most recent call last):
  File "/opt/airflow/dags/fraud_detection_training.py", line 187, in train_model
    df = self._read_data_from_kafka()
         ^^^^^^^^^^^^^^^^^^^^^^^^^^^^
  File "/opt/airflow/dags/fraud_detection_training.py", line 125, in _read_data_from_kafka
    raise ValueError('No message received from Kafka')
ValueError: No message received from Kafka
[2025-07-30T05:48:25.188+0000] {fraud_detection_training_dag.py:28} ERROR - Training failed: No message received from Kafka
Traceback (most recent call last):
  File "/opt/airflow/dags/fraud_detection_training_dag.py", line 24, in _train_model
    model, precision = trainer.train_model()
                       ^^^^^^^^^^^^^^^^^^^^^
  File "/opt/airflow/dags/fraud_detection_training.py", line 187, in train_model
    df = self._read_data_from_kafka()
         ^^^^^^^^^^^^^^^^^^^^^^^^^^^^
  File "/opt/airflow/dags/fraud_detection_training.py", line 125, in _read_data_from_kafka
    raise ValueError('No message received from Kafka')
ValueError: No message received from Kafka
[2025-07-30T05:48:25.204+0000] {taskinstance.py:3313} ERROR - Task failed with exception
Traceback (most recent call last):
  File "/opt/airflow/dags/fraud_detection_training_dag.py", line 24, in _train_model
    model, precision = trainer.train_model()
                       ^^^^^^^^^^^^^^^^^^^^^
  File "/opt/airflow/dags/fraud_detection_training.py", line 187, in train_model
    df = self._read_data_from_kafka()
         ^^^^^^^^^^^^^^^^^^^^^^^^^^^^
  File "/opt/airflow/dags/fraud_detection_training.py", line 125, in _read_data_from_kafka
    raise ValueError('No message received from Kafka')
ValueError: No message received from Kafka

During handling of the above exception, another exception occurred:

Traceback (most recent call last):
  File "/home/airflow/.local/lib/python3.12/site-packages/airflow/models/taskinstance.py", line 768, in _execute_task
    result = _execute_callable(context=context, **execute_callable_kwargs)
             ^^^^^^^^^^^^^^^^^^^^^^^^^^^^^^^^^^^^^^^^^^^^^^^^^^^^^^^^^^^^^
  File "/home/airflow/.local/lib/python3.12/site-packages/airflow/models/taskinstance.py", line 734, in _execute_callable
    return ExecutionCallableRunner(
           ^^^^^^^^^^^^^^^^^^^^^^^^
  File "/home/airflow/.local/lib/python3.12/site-packages/airflow/utils/operator_helpers.py", line 252, in run
    return self.func(*args, **kwargs)
           ^^^^^^^^^^^^^^^^^^^^^^^^^^
  File "/home/airflow/.local/lib/python3.12/site-packages/airflow/models/baseoperator.py", line 424, in wrapper
    return func(self, *args, **kwargs)
           ^^^^^^^^^^^^^^^^^^^^^^^^^^^
  File "/home/airflow/.local/lib/python3.12/site-packages/airflow/operators/python.py", line 238, in execute
    return_value = self.execute_callable()
                   ^^^^^^^^^^^^^^^^^^^^^^^
  File "/home/airflow/.local/lib/python3.12/site-packages/airflow/operators/python.py", line 256, in execute_callable
    return runner.run(*self.op_args, **self.op_kwargs)
           ^^^^^^^^^^^^^^^^^^^^^^^^^^^^^^^^^^^^^^^^^^^
  File "/home/airflow/.local/lib/python3.12/site-packages/airflow/utils/operator_helpers.py", line 252, in run
    return self.func(*args, **kwargs)
           ^^^^^^^^^^^^^^^^^^^^^^^^^^
  File "/opt/airflow/dags/fraud_detection_training_dag.py", line 29, in _train_model
    raise AirflowException(f"Model Training failed: {str(e)}")
airflow.exceptions.AirflowException: Model Training failed: No message received from Kafka
[2025-07-30T05:48:25.219+0000] {taskinstance.py:1226} INFO - Marking task as FAILED. dag_id=fraud_detection_training, task_id=execute_training, run_id=manual__2025-07-30T05:48:05.513630+00:00, execution_date=20250730T054805, start_date=20250730T054807, end_date=20250730T054825
[2025-07-30T05:48:25.252+0000] {taskinstance.py:341} INFO - ::group::Post task execution logs
[2025-07-30T05:48:25.253+0000] {standard_task_runner.py:124} ERROR - Failed to execute job 93 for task execute_training (Model Training failed: No message received from Kafka; 1553)
Traceback (most recent call last):
  File "/opt/airflow/dags/fraud_detection_training_dag.py", line 24, in _train_model
    model, precision = trainer.train_model()
                       ^^^^^^^^^^^^^^^^^^^^^
  File "/opt/airflow/dags/fraud_detection_training.py", line 187, in train_model
    df = self._read_data_from_kafka()
         ^^^^^^^^^^^^^^^^^^^^^^^^^^^^
  File "/opt/airflow/dags/fraud_detection_training.py", line 125, in _read_data_from_kafka
    raise ValueError('No message received from Kafka')
ValueError: No message received from Kafka

During handling of the above exception, another exception occurred:

Traceback (most recent call last):
  File "/home/airflow/.local/lib/python3.12/site-packages/airflow/task/task_runner/standard_task_runner.py", line 117, in _start_by_fork
    ret = args.func(args, dag=self.dag)
          ^^^^^^^^^^^^^^^^^^^^^^^^^^^^^
  File "/home/airflow/.local/lib/python3.12/site-packages/airflow/cli/cli_config.py", line 49, in command
    return func(*args, **kwargs)
           ^^^^^^^^^^^^^^^^^^^^^
  File "/home/airflow/.local/lib/python3.12/site-packages/airflow/utils/cli.py", line 116, in wrapper
    return f(*args, **kwargs)
           ^^^^^^^^^^^^^^^^^^
  File "/home/airflow/.local/lib/python3.12/site-packages/airflow/cli/commands/task_command.py", line 483, in task_run
    task_return_code = _run_task_by_selected_method(args, _dag, ti)
                       ^^^^^^^^^^^^^^^^^^^^^^^^^^^^^^^^^^^^^^^^^^^^
  File "/home/airflow/.local/lib/python3.12/site-packages/airflow/cli/commands/task_command.py", line 256, in _run_task_by_selected_method
    return _run_raw_task(args, ti)
           ^^^^^^^^^^^^^^^^^^^^^^^
  File "/home/airflow/.local/lib/python3.12/site-packages/airflow/cli/commands/task_command.py", line 341, in _run_raw_task
    return ti._run_raw_task(
           ^^^^^^^^^^^^^^^^^
  File "/home/airflow/.local/lib/python3.12/site-packages/airflow/utils/session.py", line 97, in wrapper
    return func(*args, session=session, **kwargs)
           ^^^^^^^^^^^^^^^^^^^^^^^^^^^^^^^^^^^^^^
  File "/home/airflow/.local/lib/python3.12/site-packages/airflow/models/taskinstance.py", line 3006, in _run_raw_task
    return _run_raw_task(
           ^^^^^^^^^^^^^^
  File "/home/airflow/.local/lib/python3.12/site-packages/airflow/models/taskinstance.py", line 274, in _run_raw_task
    TaskInstance._execute_task_with_callbacks(
  File "/home/airflow/.local/lib/python3.12/site-packages/airflow/models/taskinstance.py", line 3161, in _execute_task_with_callbacks
    result = self._execute_task(context, task_orig)
             ^^^^^^^^^^^^^^^^^^^^^^^^^^^^^^^^^^^^^^
  File "/home/airflow/.local/lib/python3.12/site-packages/airflow/models/taskinstance.py", line 3185, in _execute_task
    return _execute_task(self, context, task_orig)
           ^^^^^^^^^^^^^^^^^^^^^^^^^^^^^^^^^^^^^^^
  File "/home/airflow/.local/lib/python3.12/site-packages/airflow/models/taskinstance.py", line 768, in _execute_task
    result = _execute_callable(context=context, **execute_callable_kwargs)
             ^^^^^^^^^^^^^^^^^^^^^^^^^^^^^^^^^^^^^^^^^^^^^^^^^^^^^^^^^^^^^
  File "/home/airflow/.local/lib/python3.12/site-packages/airflow/models/taskinstance.py", line 734, in _execute_callable
    return ExecutionCallableRunner(
           ^^^^^^^^^^^^^^^^^^^^^^^^
  File "/home/airflow/.local/lib/python3.12/site-packages/airflow/utils/operator_helpers.py", line 252, in run
    return self.func(*args, **kwargs)
           ^^^^^^^^^^^^^^^^^^^^^^^^^^
  File "/home/airflow/.local/lib/python3.12/site-packages/airflow/models/baseoperator.py", line 424, in wrapper
    return func(self, *args, **kwargs)
           ^^^^^^^^^^^^^^^^^^^^^^^^^^^
  File "/home/airflow/.local/lib/python3.12/site-packages/airflow/operators/python.py", line 238, in execute
    return_value = self.execute_callable()
                   ^^^^^^^^^^^^^^^^^^^^^^^
  File "/home/airflow/.local/lib/python3.12/site-packages/airflow/operators/python.py", line 256, in execute_callable
    return runner.run(*self.op_args, **self.op_kwargs)
           ^^^^^^^^^^^^^^^^^^^^^^^^^^^^^^^^^^^^^^^^^^^
  File "/home/airflow/.local/lib/python3.12/site-packages/airflow/utils/operator_helpers.py", line 252, in run
    return self.func(*args, **kwargs)
           ^^^^^^^^^^^^^^^^^^^^^^^^^^
  File "/opt/airflow/dags/fraud_detection_training_dag.py", line 29, in _train_model
    raise AirflowException(f"Model Training failed: {str(e)}")
airflow.exceptions.AirflowException: Model Training failed: No message received from Kafka
[2025-07-30T05:48:25.299+0000] {local_task_job_runner.py:266} INFO - Task exited with return code 1
[2025-07-30T05:48:25.320+0000] {taskinstance.py:3901} INFO - 1 downstream tasks scheduled from follow-on schedule check
[2025-07-30T05:48:25.323+0000] {local_task_job_runner.py:245} INFO - ::endgroup::
